Workbook

Sheet Premissas
B1: CALCULADORA BESS — LOAD SHIFT GRUPO A — 4 CENÁRIOS
B2: Amarelo = input | Verde = calculado | Salmão = gerador diesel
B3: TARIFAS
B4: Tarifa fora ponta | C4: 0.6 | D4: R$/kWh
B5: Tarifa ponta | C5: 3.89 | D5: R$/kWh
B7: CONSUMO
B8: Consumo na ponta | C8: 4500 | D8: kWh/mês
B9: Consumo fora ponta | C9: 30000 | D9: kWh/mês | E9: Total do cliente no período fora ponta
B10: Consumo para carregar BESS | C10: =IFERROR(C8/C20,0) -> 4932.1338 | D10: kWh/mês | E10: consumo ponta ÷ η round-trip
B11: Consumo fora ponta + BESS | C11: =IFERROR(C9+C10,0) -> 34932.134 | D11: kWh/mês | E11: consumo FP atual + carga do BESS
B12: Dias úteis com ponta por mês | C12: 21 | D12: dias
B13: Horas de ponta por dia | C13: 3 | D13: h/dia
B15: SISTEMA BESS
B16: Profundidade de descarga (DoD) | C16: 0.9 | D16: %
B17: η carga AC→DC | C17: 0.96 | D17: % | E17: Eficiência de carga do inversor (AC para DC)
B18: η bateria LFP | C18: 0.99 | D18: % | E18: Eficiência interna da bateria no ciclo
B19: η descarga DC→AC | C19: 0.96 | D19: % | E19: Eficiência de descarga do inversor (DC para AC)
B20: η round-trip (calculado) | C20: =C17*C18*C19 -> 0.912384 | D20: % | E20: η carga × η bateria × η descarga
B21: Degradação anual da bateria | C21: 0.02 | D21: %/ano
B22: Vida útil para análise | C22: 12 | D22: anos
B24: SISTEMA SOLAR - PREMISSAS PARA OS CENÁRIOS C2 E C3
B25: Geração estimada por kWp | C25: 120 | D25: kWh/kWp/mês | E25: Referência Brasil: 100–130 kWh/kWp/mês
B26: Custo solar instalado | C26: 2000 | D26: R$/kWp | E26: C&I 2025: R$ 1.800 – 2.500/kWp instalado
B28: Solar — C2 (cobre só o BESS)
B29: kWp sugerido C2 | C29: =IFERROR(C10/C25,0) -> 41.101115 | D29: kWp | E29: consumo carregar BESS ÷ geração/kWp
B30: kWp instalado C2 | C30: 42 | D30: kWp
B31: Geração solar mensal C2 | C31: =IFERROR(C30*C25,0) -> 5040 | D31: kWh/mês
B33: Solar — C3 (BESS + consumo FP)
B34: kWp sugerido C3 | C34: =IFERROR((C10+C9)/C25,0) -> 291.10112 | D34: kWp | E34: (consumo carregar BESS + consumo FP) ÷ geração/kWp
B35: kWp instalado C3 | C35: 292 | D35: kWp
B36: Geração solar mensal C3 | C36: =IFERROR(C35*C25,0) -> 35040 | D36: kWh/mês
B38: FINANCEIRO
B39: CAPEX BESS instalado por kWh | C39: 1800 | D39: R$/kWh
B40: O&M anual (% do CAPEX total) | C40: 0.005 | D40: %/ano
B41: Taxa de desconto (TMA) | C41: 0.12 | D41: %/ano
B42: Reajuste tarifário anual | C42: 0.07 | D42: %/ano
B44: GERADOR DIESEL — Cenário C4
B45: CAPEX gerador (compra + instalação) | C45: 220000 | D45: R$ | E45: Inclui ART, quadro e instalação elétrica ( R$ 1.500 a R$ 2.800/kVA )
B46: Fator de potência cos φ | C46: 0.8 | D46: % | E46: Padrão de mercado para geradores diesel
B47: Margem de segurança | C47: 0.2 | D47: % | E47: Para partida de motores e folga operacional
...

Sheet C1 - BESS Puro
B1: CENÁRIO 1 — BESS PURO (sem fotovoltaico)
B3: DIMENSIONAMENTO DO BESS
B4: Consumo diário na ponta | C4: =Premissas!C8/Premissas!C12 -> 214.28571 | D4: kWh/dia | E4: consumo ponta mensal ÷ dias úteis
B5: Capacidade nominal do BESS | C5: =C4/(Premissas!C19*Premissas!C16) -> 248.01587 | D5: kWh | E5: consumo diário ÷ (η descarga × DoD)
B6: Potência do inversor | C6: =C5/Premissas!C13 -> 82.671958 | D6: kW | E6: capacidade ÷ horas de ponta
B8: ECONOMIA MENSAL
B9: Receita ponta evitada | C9: =Premissas!C8*Premissas!C5 -> 17505 | D9: R$/mês | E9: consumo ponta × tarifa ponta
B10: (−) Custo recarga da rede | C10: =Premissas!C10*Premissas!C4 -> 2959.2803 | D10: R$/mês | E10: consumo carregar BESS × tarifa FP
B11: Economia líquida mensal | C11: =C9-C10 -> 14545.72 | D11: R$/mês
B12: Economia líquida anual | C12: =C11*12 -> 174548.64 | D12: R$/ano
B14: CAPEX E RETORNO
B15: CAPEX BESS | C15: =C5*Premissas!C39 -> 446428.57 | D15: R$
B16: O&M anual | C16: =C15*Premissas!C40 -> 2232.1429 | D16: R$/ano
B17: Economia líquida anual | C17: =C12-C16 -> 172316.49 | D17: R$/ano
B18: Payback simples | C18: =IFERROR(INT(C15/C17)&" anos e "&ROUND((C15/C17-INT(C15/C17))*12,0)&" meses","Não paga no período") -> 2 anos e 7 meses
B19: Payback com reajuste tarifário | C19: =IFERROR(INT((MATCH(0,'Fluxo de Caixa'!C$4:C$16,1)-1)+ABS(INDEX('Fluxo de Caixa'!C$4:C$16,MATCH(0,'Fluxo de Caixa'!C$4:C$16,1)))/(INDEX('Fluxo de Caixa'!C$4:C$16,MATCH(0,'Fluxo de Caixa'!C$4:C$16,1)+1)-INDEX('Fluxo de Caixa'!C$4:C$16,MATCH(0,'Fluxo de Caixa'!C$4:C$16,1))))&" anos e "&ROUND(((MATCH(0,'Fluxo de Caixa'!C$4:C$16,1)-1)+ABS(INDEX('Fluxo de Caixa'!C$4:C$16,MATCH(0,'Fluxo de Caixa'!C$4:C$16,1)))/(INDEX('Fluxo de Caixa'!C$4:C$16,MATCH(0,'Fluxo de Caixa'!C$4:C$16,1)+1)-INDEX('Fluxo de Caixa'!C$4:C$16,MATCH(0,'Fluxo de Caixa'!C$4:C$16,1)))-INT((MATCH(0,'Fluxo de Caixa'!C$4:C$16,1)-1)+ABS(INDEX('Fluxo de Caixa'!C$4:C$16,MATCH(0,'Fluxo de Caixa'!C$4:C$16,1)))/(INDEX('Fluxo de Caixa'!C$4:C$16,MATCH(0,'Fluxo de Caixa'!C$4:C$16,1)+1)-INDEX('Fluxo de Caixa'!C$4:C$16,MATCH(0,'Fluxo de Caixa'!C$4:C$16,1)))))*12,0)&" meses","Não paga no período") -> 2 anos e 6 meses | E19: Considera reajuste tarifário e degradação — payback real
B20: Economia acumulada 12 anos | C20: =SUM('Fluxo de Caixa'!B5:B16) -> 2729116 | E20: Fluxos líquidos anuais somados — com reajuste tarifário e degradação da bateria

Sheet C2 - BESS+Solar BESS
B1: CENÁRIO 2 — BESS + SOLAR PARA CARREGAR O BESS
B3: DIMENSIONAMENTO DO BESS
B4: Consumo diário na ponta | C4: =Premissas!C8/Premissas!C12 -> 214.28571 | D4: kWh/dia | E4: consumo ponta mensal ÷ dias úteis
B5: Capacidade nominal do BESS | C5: =C4/(Premissas!C19*Premissas!C16) -> 248.01587 | D5: kWh | E5: consumo diário ÷ (η descarga × DoD)
B6: Potência do inversor | C6: =C5/Premissas!C13 -> 82.671958 | D6: kW | E6: capacidade ÷ horas de ponta
B8: SOLAR E COMPENSAÇÃO
B9: kWp sugerido C2 | C9: =Premissas!C29 -> 41.101115 | D9: kWp | E9: mínimo para cobrir recarga do BESS
B10: kWp instalado C2 | C10: =Premissas!C30 -> 42 | D10: kWp
B11: Geração solar mensal | C11: =Premissas!C31 -> 5040 | D11: kWh/mês
B12: Cobertura da recarga pelo solar | C12: =MIN(C11,Premissas!C10) -> 4932.1338 | D12: kWh/mês | E12: mín(geração, consumo carregar BESS)
B13: Saldo solar após recarga | C13: =MAX(0,C11-Premissas!C10) -> 107.86616 | D13: kWh/mês | E13: excedente após cobrir o BESS
B14: Abatimento no consumo FP | C14: =MIN(C13,Premissas!C9) -> 107.86616 | D14: kWh/mês | E14: saldo que abate consumo FP via compensação
B15: Recarga residual da rede | C15: =MAX(0,Premissas!C10-C11) -> 0 | D15: kWh/mês
B17: ECONOMIA MENSAL
B18: Receita ponta evitada | C18: =Premissas!C8*Premissas!C5 -> 17505 | D18: R$/mês
B19: (−) Custo recarga residual | C19: =C15*Premissas!C4 -> 0 | D19: R$/mês
B20: Economia FP pelo saldo solar | C20: =C14*Premissas!C4 -> 64.719697 | D20: R$/mês
B21: Economia líquida mensal | C21: =C18-C19+C20 -> 17569.72 | D21: R$/mês
B22: Economia líquida anual | C22: =C21*12 -> 210836.64 | D22: R$/ano
B24: CAPEX E RETORNO
B25: CAPEX BESS | C25: =C5*Premissas!C39 -> 446428.57 | D25: R$
B26: CAPEX solar C2 | C26: =Premissas!C30*Premissas!C26 -> 84000 | D26: R$
B27: CAPEX total | C27: =C25+C26 -> 530428.57 | D27: R$
B28: O&M anual | C28: =C27*Premissas!C40 -> 2652.1429 | D28: R$/ano
B29: Economia líquida anual | C29: =C22-C28 -> 208184.49 | D29: R$/ano
B30: Payback simples | C30: =IFERROR(INT(C27/C29)&" anos e "&ROUND((C27/C29-INT(C27/C29))*12,0)&" meses","Não paga no período") -> 2 anos e 7 meses
B31: Payback com reajuste tarifário | C31: =IFERROR(INT((MATCH(0,'Fluxo de Caixa'!E$4:E$16,1)-1)+ABS(INDEX('Fluxo de Caixa'!E$4:E$16,MATCH(0,'Fluxo de Caixa'!E$4:E$16,1)))/(INDEX('Fluxo de Caixa'!E$4:E$16,MATCH(0,'Fluxo de Caixa'!E$4:E$16,1)+1)-INDEX('Fluxo de Caixa'!E$4:E$16,MATCH(0,'Fluxo de Caixa'!E$4:E$16,1))))&" anos e "&ROUND(((MATCH(0,'Fluxo de Caixa'!E$4:E$16,1)-1)+ABS(INDEX('Fluxo de Caixa'!E$4:E$16,MATCH(0,'Fluxo de Caixa'!E$4:E$16,1)))/(INDEX('Fluxo de Caixa'!E$4:E$16,MATCH(0,'Fluxo de Caixa'!E$4:E$16,1)+1)-INDEX('Fluxo de Caixa'!E$4:E$16,MATCH(0,'Fluxo de Caixa'!E$4:E$16,1)))-INT((MATCH(0,'Fluxo de Caixa'!E$4:E$16,1)-1)+ABS(INDEX('Fluxo de Caixa'!E$4:E$16,MATCH(0,'Fluxo de Caixa'!E$4:E$16,1)))/(INDEX('Fluxo de Caixa'!E$4:E$16,MATCH(0,'Fluxo de Caixa'!E$4:E$16,1)+1)-INDEX('Fluxo de Caixa'!E$4:E$16,MATCH(0,'Fluxo de Caixa'!E$4:E$16,1)))))*12,0)&" meses","Não paga no período") -> 2 anos e 5 meses | E31: Considera reajuste tarifário e degradação — payback real
B32: Economia acumulada 12 anos | C32: =SUM('Fluxo de Caixa'!D5:D16) -> 3297017.6 | E32: Fluxos líquidos anuais somados — com reajuste tarifário e degradação da bateria

Sheet C3 - BESS+Solar FP
B1: CENÁRIO 3 — BESS + SOLAR PARA BESS E CONSUMO FORA PONTA
B3: DIMENSIONAMENTO DO BESS
B4: Consumo diário na ponta | C4: =Premissas!C8/Premissas!C12 -> 214.28571 | D4: kWh/dia | E4: consumo ponta mensal ÷ dias úteis
B5: Capacidade nominal do BESS | C5: =C4/(Premissas!C19*Premissas!C16) -> 248.01587 | D5: kWh | E5: consumo diário ÷ (η descarga × DoD)
B6: Potência do inversor | C6: =C5/Premissas!C13 -> 82.671958 | D6: kW | E6: capacidade ÷ horas de ponta
B8: SOLAR E COMPENSAÇÃO
B9: kWp sugerido C3 | C9: =Premissas!C34 -> 291.10112 | D9: kWp | E9: mínimo para cobrir BESS e consumo FP
B10: kWp instalado C3 | C10: =Premissas!C35 -> 292 | D10: kWp
B11: Geração solar mensal | C11: =Premissas!C36 -> 35040 | D11: kWh/mês
B12: Cobertura da recarga pelo solar | C12: =MIN(C11,Premissas!C10) -> 4932.1338 | D12: kWh/mês
B13: Saldo solar após recarga | C13: =MAX(0,C11-Premissas!C10) -> 30107.866 | D13: kWh/mês
B14: Abatimento no consumo FP | C14: =MIN(C13,Premissas!C9) -> 30000 | D14: kWh/mês
B15: Consumo FP remanescente pago | C15: =MAX(0,Premissas!C9-C14) -> 0 | D15: kWh/mês
B16: Recarga residual da rede | C16: =MAX(0,Premissas!C10-C11) -> 0 | D16: kWh/mês
B18: ECONOMIA MENSAL
B19: Receita ponta evitada | C19: =Premissas!C8*Premissas!C5 -> 17505 | D19: R$/mês
B20: (−) Custo recarga residual | C20: =C16*Premissas!C4 -> 0 | D20: R$/mês
B21: Economia FP = abatimento solar | C21: =C14*Premissas!C4 -> 18000 | D21: R$/mês
B22: Economia líquida mensal | C22: =C19-C20+C21 -> 35505 | D22: R$/mês
B23: Economia líquida anual | C23: =C22*12 -> 426060 | D23: R$/ano
B25: CAPEX E RETORNO
B26: CAPEX BESS | C26: =C5*Premissas!C39 -> 446428.57 | D26: R$
B27: CAPEX solar C3 | C27: =Premissas!C35*Premissas!C26 -> 584000 | D27: R$
B28: CAPEX total | C28: =C26+C27 -> 1030428.6 | D28: R$
B29: O&M anual | C29: =C28*Premissas!C40 -> 5152.1429 | D29: R$/ano
B30: Economia líquida anual | C30: =C23-C29 -> 420907.86 | D30: R$/ano
B31: Payback simples | C31: =IFERROR(INT(C28/C30)&" anos e "&ROUND((C28/C30-INT(C28/C30))*12,0)&" meses","Não paga no período") -> 2 anos e 5 meses
B32: Payback com reajuste tarifário | C32: =IFERROR(INT((MATCH(0,'Fluxo de Caixa'!G$4:G$16,1)-1)+ABS(INDEX('Fluxo de Caixa'!G$4:G$16,MATCH(0,'Fluxo de Caixa'!G$4:G$16,1)))/(INDEX('Fluxo de Caixa'!G$4:G$16,MATCH(0,'Fluxo de Caixa'!G$4:G$16,1)+1)-INDEX('Fluxo de Caixa'!G$4:G$16,MATCH(0,'Fluxo de Caixa'!G$4:G$16,1))))&" anos e "&ROUND(((MATCH(0,'Fluxo de Caixa'!G$4:G$16,1)-1)+ABS(INDEX('Fluxo de Caixa'!G$4:G$16,MATCH(0,'Fluxo de Caixa'!G$4:G$16,1)))/(INDEX('Fluxo de Caixa'!G$4:G$16,MATCH(0,'Fluxo de Caixa'!G$4:G$16,1)+1)-INDEX('Fluxo de Caixa'!G$4:G$16,MATCH(0,'Fluxo de Caixa'!G$4:G$16,1)))-INT((MATCH(0,'Fluxo de Caixa'!G$4:G$16,1)-1)+ABS(INDEX('Fluxo de Caixa'!G$4:G$16,MATCH(0,'Fluxo de Caixa'!G$4:G$16,1)))/(INDEX('Fluxo de Caixa'!G$4:G$16,MATCH(0,'Fluxo de Caixa'!G$4:G$16,1)+1)-INDEX('Fluxo de Caixa'!G$4:G$16,MATCH(0,'Fluxo de Caixa'!G$4:G$16,1)))))*12,0)&" meses","Não paga no período") -> 2 anos e 4 meses | E32: Considera reajuste tarifário e degradação — payback real
B33: Economia acumulada 12 anos | C33: =SUM('Fluxo de Caixa'!F5:F16) -> 6665121.7 | E33: Fluxos líquidos anuais somados — com reajuste tarifário e degradação da bateria

Sheet C4 - Gerador Diesel
B1: CENÁRIO 4 — GERADOR DIESEL (comparativo)
B3: DIMENSIONAMENTO DO GERADOR
B4: Potência calculada (kW) | C4: =Premissas!C53 -> 71.428571 | D4: kW | E4: consumo ponta ÷ dias úteis ÷ horas ponta — sem DoD, gerador entrega em tempo real
B5: kVA nominal para instalação | C5: =Premissas!C54 -> 107.14286 | D5: kVA | E5: (kW ÷ cos φ) × (1 + margem) — use para orçar o equipamento
B6: Horas de operação mensal | C6: =Premissas!C13*Premissas!C12 -> 63 | D6: h/mês | E6: horas de ponta/dia × dias úteis/mês
B7: Consumo diesel por hora | C7: =C4*Premissas!C48 -> 20 | D7: L/h | E7: potência kW × consumo específico L/kWh
B8: Consumo diesel mensal | C8: =C7*C6 -> 1260 | D8: L | E8: L/h × horas de operação mensal
B9: Custo combustível mensal | C9: =C8*Premissas!C49 -> 9198 | D9: R$/mês | E9: litros × preço diesel
B11: ECONOMIA MENSAL
B12: Receita ponta evitada | C12: =Premissas!C8*Premissas!C5 -> 17505 | D12: R$/mês | E12: consumo ponta × tarifa ponta
B13: (−) Custo combustível | C13: =C9 -> 9198 | D13: R$/mês
B14: Economia líquida mensal | C14: =C12-C13 -> 8307 | D14: R$/mês
B15: Receita ponta anual (base) | C15: =C12*12 -> 210060 | D15: R$/ano | E15: base para o fluxo de caixa com reajuste tarifário
B16: Custo diesel anual (base) | C16: =C13*12 -> 110376 | D16: R$/ano | E16: base para o fluxo com reajuste do diesel
B17: Economia Bruta anual | C17: =C14*12 -> 99684 | D17: R$/ano
B19: CAPEX E RETORNO
B20: CAPEX gerador | C20: =Premissas!C45 -> 220000 | D20: R$
B21: Manutenção anual | C21: =Premissas!C50 -> 10000 | D21: R$/ano
B22: Economia líquida anual | C22: =C17-C21 -> 89684 | D22: R$/ano
B23: Payback simples | C23: =IFERROR(INT(C20/C22)&" anos e "&ROUND((C20/C22-INT(C20/C22))*12,0)&" meses","Não paga no período") -> 2 anos e 5 meses
B24: Payback com reajuste tarifário | C24: =IFERROR(INT((MATCH(0,'Fluxo de Caixa'!I$4:I$16,1)-1)+ABS(INDEX('Fluxo de Caixa'!I$4:I$16,MATCH(0,'Fluxo de Caixa'!I$4:I$16,1)))/(INDEX('Fluxo de Caixa'!I$4:I$16,MATCH(0,'Fluxo de Caixa'!I$4:I$16,1)+1)-INDEX('Fluxo de Caixa'!I$4:I$16,MATCH(0,'Fluxo de Caixa'!I$4:I$16,1))))&" anos e "&ROUND(((MATCH(0,'Fluxo de Caixa'!I$4:I$16,1)-1)+ABS(INDEX('Fluxo de Caixa'!I$4:I$16,MATCH(0,'Fluxo de Caixa'!I$4:I$16,1)))/(INDEX('Fluxo de Caixa'!I$4:I$16,MATCH(0,'Fluxo de Caixa'!I$4:I$16,1)+1)-INDEX('Fluxo de Caixa'!I$4:I$16,MATCH(0,'Fluxo de Caixa'!I$4:I$16,1)))-INT((MATCH(0,'Fluxo de Caixa'!I$4:I$16,1)-1)+ABS(INDEX('Fluxo de Caixa'!I$4:I$16,MATCH(0,'Fluxo de Caixa'!I$4:I$16,1)))/(INDEX('Fluxo de Caixa'!I$4:I$16,MATCH(0,'Fluxo de Caixa'!I$4:I$16,1)+1)-INDEX('Fluxo de Caixa'!I$4:I$16,MATCH(0,'Fluxo de Caixa'!I$4:I$16,1)))))*12,0)&" meses","Não paga no período") -> 2 anos e 4 meses | E24: Considera reajuste tarifário e degradação — payback real
B25: Economia acumulada 12 anos | C25: =SUM('Fluxo de Caixa'!H5:H16) -> 1663192.4 | E25: Fluxos líquidos anuais somados — com reajuste tarifário e degradação da bateria

Sheet Comparativo
B1: COMPARATIVO — C1 BESS × C2 Solar→BESS × C3 Solar→FP × C4 Diesel
C3: C1 — BESS Puro | D3: C2 — Solar→BESS | E3: C3 — Solar→FP | F3: C4 — Gerador
B4: SISTEMA
B5: Capacidade BESS (kWh) | C5: ='C1 - BESS Puro'!C5 -> 248.01587 | D5: ='C2 - BESS+Solar BESS'!C5 -> 248.01587 | E5: ='C3 - BESS+Solar FP'!C5 -> 248.01587 | F5: —
B6: Potência inversor / gerador (kW) | C6: ='C1 - BESS Puro'!C6 -> 82.671958 | D6: ='C2 - BESS+Solar BESS'!C6 -> 82.671958 | E6: ='C3 - BESS+Solar FP'!C6 -> 82.671958 | F6: =Premissas!C53 -> 71.428571
B7: kVA nominal gerador | C7: — | D7: — | E7: — | F7: =Premissas!C54 -> 107.14286
B8: kWp solar instalado | C8: — | D8: =Premissas!C30 -> 42 | E8: =Premissas!C35 -> 292 | F8: —
B10: CAPEX
B11: CAPEX BESS (R$) | C11: ='C1 - BESS Puro'!C15 -> 446428.57 | D11: ='C2 - BESS+Solar BESS'!C25 -> 446428.57 | E11: ='C3 - BESS+Solar FP'!C26 -> 446428.57 | F11: —
B12: CAPEX Solar / Gerador (R$) | C12: — | D12: ='C2 - BESS+Solar BESS'!C26 -> 84000 | E12: ='C3 - BESS+Solar FP'!C27 -> 584000 | F12: =Premissas!C45 -> 220000
B13: CAPEX Total (R$) | C13: ='C1 - BESS Puro'!C15 -> 446428.57 | D13: ='C2 - BESS+Solar BESS'!C27 -> 530428.57 | E13: ='C3 - BESS+Solar FP'!C28 -> 1030428.6 | F13: =Premissas!C45 -> 220000
B15: ECONOMIA MENSAL
B16: Receita ponta evitada | C16: ='C1 - BESS Puro'!C9 -> 17505 | D16: ='C2 - BESS+Solar BESS'!C18 -> 17505 | E16: ='C3 - BESS+Solar FP'!C19 -> 17505 | F16: ='C4 - Gerador Diesel'!C12 -> 17505
B17: (−) Custo variável | C17: ='C1 - BESS Puro'!C10 -> 2959.2803 | D17: ='C2 - BESS+Solar BESS'!C19 -> 0 | E17: ='C3 - BESS+Solar FP'!C20 -> 0 | F17: ='C4 - Gerador Diesel'!C13 -> 9198 | G17: BESS = recarga FP | Diesel = combustível
B18: Economia FP solar | C18: — | D18: ='C2 - BESS+Solar BESS'!C20 -> 64.719697 | E18: ='C3 - BESS+Solar FP'!C21 -> 18000 | F18: —
B19: Economia mensal | C19: ='C1 - BESS Puro'!C11 -> 14545.72 | D19: ='C2 - BESS+Solar BESS'!C21 -> 17569.72 | E19: ='C3 - BESS+Solar FP'!C22 -> 35505 | F19: ='C4 - Gerador Diesel'!C14 -> 8307
B20: Economia anual | C20: ='C1 - BESS Puro'!C12 -> 174548.64 | D20: ='C2 - BESS+Solar BESS'!C22 -> 210836.64 | E20: ='C3 - BESS+Solar FP'!C23 -> 426060 | F20: ='C4 - Gerador Diesel'!C17 -> 99684
B22: RETORNO FINANCEIRO
B23: O&M / Manutenção anual (R$) | C23: ='C1 - BESS Puro'!C16 -> 2232.1429 | D23: ='C2 - BESS+Solar BESS'!C28 -> 2652.1429 | E23: ='C3 - BESS+Solar FP'!C29 -> 5152.1429 | F23: =Premissas!C50 -> 10000
B24: Economia líquida anual | C24: ='C1 - BESS Puro'!C17 -> 172316.49 | D24: ='C2 - BESS+Solar BESS'!C29 -> 208184.49 | E24: ='C3 - BESS+Solar FP'!C30 -> 420907.86 | F24: ='C4 - Gerador Diesel'!C22 -> 89684
B25: Payback simples | C25: ='C1 - BESS Puro'!C18 -> 2 anos e 7 meses | D25: ='C2 - BESS+Solar BESS'!C30 -> 2 anos e 7 meses | E25: ='C3 - BESS+Solar FP'!C31 -> 2 anos e 5 meses | F25: ='C4 - Gerador Diesel'!C23 -> 2 anos e 5 meses
B26: Payback com reajuste tarifário | C26: ='C1 - BESS Puro'!C19 -> 2 anos e 6 meses | D26: ='C2 - BESS+Solar BESS'!C31 -> 2 anos e 5 meses | E26: ='C3 - BESS+Solar FP'!C32 -> 2 anos e 4 meses | F26: ='C4 - Gerador Diesel'!C24 -> 2 anos e 4 meses
B28: ECONOMIA ACUMULADA 12 ANOS
B29: Economia acumulada 12 anos | C29: ='C1 - BESS Puro'!C20 -> 2729116 | D29: ='C2 - BESS+Solar BESS'!C32 -> 3297017.6 | E29: ='C3 - BESS+Solar FP'!C33 -> 6665121.7 | F29: ='C4 - Gerador Diesel'!C25 -> 1663192.4 | G29: Com reajuste tarifário + degradação — fluxos líquidos anuais somados
B31: INDICADORES — projeção 12 anos
B32: VPL — Valor Presente Líquido | C32: ='Fluxo de Caixa'!B18 -> 875432.4 | D32: ='Fluxo de Caixa'!D18 -> 1066515.2 | E32: ='Fluxo de Caixa'!F18 -> 2197969.6 | F32: ='Fluxo de Caixa'!H18 -> 559226.76
B33: TIR — Taxa Interna de Retorno | C33: ='Fluxo de Caixa'!B19 -> 0.4254002 | D33: ='Fluxo de Caixa'!D19 -> 0.43227977 | E33: ='Fluxo de Caixa'!F19 -> 0.44915216 | F33: ='Fluxo de Caixa'!H19 -> 0.47510196

Sheet Fluxo de Caixa
A1: FLUXO DE CAIXA ACUMULADO — COMPARAÇÃO DOS 4 CENÁRIOS
A3: Ano | B3: C1 Liq. | C3: C1 Acum. | D3: C2 Liq. | E3: C2 Acum. | F3: C3 Liq. | G3: C3 Acum. | H3: C4 Liq. | I3: C4 Acum.
A4: 0 | B4: =-'C1 - BESS Puro'!C15 -> -446428.57 | C4: =B4 -> -446428.57 | D4: =-'C2 - BESS+Solar BESS'!C27 -> -530428.57 | E4: =D4 -> -530428.57 | F4: =-'C3 - BESS+Solar FP'!C28 -> -1030428.6 | G4: =F4 -> -1030428.6 | H4: =-'C4 - Gerador Diesel'!C20 -> -220000 | I4: =H4 -> -220000
A5: 1 | B5: ='C1 - BESS Puro'!$C$12*(1-Premissas!$C$21)^(A5-1)*(1+Premissas!$C$42)^(A5-1)-'C1 - BESS Puro'!$C$16 -> 172316.49 | C5: =C4+B5 -> -274112.08 | D5: ='C2 - BESS+Solar BESS'!$C$22*(1-Premissas!$C$21)^(A5-1)*(1+Premissas!$C$42)^(A5-1)-'C2 - BESS+Solar BESS'!$C$28 -> 208184.49 | E5: =E4+D5 -> -322244.08 | F5: ='C3 - BESS+Solar FP'!$C$23*(1-Premissas!$C$21)^(A5-1)*(1+Premissas!$C$42)^(A5-1)-'C3 - BESS+Solar FP'!$C$29 -> 420907.86 | G5: =G4+F5 -> -609520.71 | H5: ='C4 - Gerador Diesel'!$C$15*(1+Premissas!$C$42)^(A5-1)-'C4 - Gerador Diesel'!$C$16*(1+Premissas!$C$51)^(A5-1)-Premissas!$C$50 -> 89684 | I5: =I4+H5 -> -130316
A6: 2 | B6: ='C1 - BESS Puro'!$C$12*(1-Premissas!$C$21)^(A6-1)*(1+Premissas!$C$42)^(A6-1)-'C1 - BESS Puro'!$C$16 -> 180799.56 | C6: =C5+B6 -> -93312.521 | D6: ='C2 - BESS+Solar BESS'!$C$22*(1-Premissas!$C$21)^(A6-1)*(1+Premissas!$C$42)^(A6-1)-'C2 - BESS+Solar BESS'!$C$28 -> 218431.15 | E6: =E5+D6 -> -103812.92 | F6: ='C3 - BESS+Solar FP'!$C$23*(1-Premissas!$C$21)^(A6-1)*(1+Premissas!$C$42)^(A6-1)-'C3 - BESS+Solar FP'!$C$29 -> 441614.37 | G6: =G5+F6 -> -167906.34 | H6: ='C4 - Gerador Diesel'!$C$15*(1+Premissas!$C$42)^(A6-1)-'C4 - Gerador Diesel'!$C$16*(1+Premissas!$C$51)^(A6-1)-Premissas!$C$50 -> 96661.88 | I6: =I5+H6 -> -33654.12
A7: 3 | B7: ='C1 - BESS Puro'!$C$12*(1-Premissas!$C$21)^(A7-1)*(1+Premissas!$C$42)^(A7-1)-'C1 - BESS Puro'!$C$16 -> 189694.9 | C7: =C6+B7 -> 96382.377 | D7: ='C2 - BESS+Solar BESS'!$C$22*(1-Premissas!$C$21)^(A7-1)*(1+Premissas!$C$42)^(A7-1)-'C2 - BESS+Solar BESS'!$C$28 -> 229175.8 | E7: =E6+D7 -> 125362.88 | F7: ='C3 - BESS+Solar FP'!$C$23*(1-Premissas!$C$21)^(A7-1)*(1+Premissas!$C$42)^(A7-1)-'C3 - BESS+Solar FP'!$C$29 -> 463327.23 | G7: =G6+F7 -> 295420.88 | H7: ='C4 - Gerador Diesel'!$C$15*(1+Premissas!$C$42)^(A7-1)-'C4 - Gerador Diesel'!$C$16*(1+Premissas!$C$51)^(A7-1)-Premissas!$C$50 -> 104128.21 | I7: =I6+H7 -> 70474.092
A8: 4 | B8: ='C1 - BESS Puro'!$C$12*(1-Premissas!$C$21)^(A8-1)*(1+Premissas!$C$42)^(A8-1)-'C1 - BESS Puro'!$C$16 -> 199022.55 | C8: =C7+B8 -> 295404.93 | D8: ='C2 - BESS+Solar BESS'!$C$22*(1-Premissas!$C$21)^(A8-1)*(1+Premissas!$C$42)^(A8-1)-'C2 - BESS+Solar BESS'!$C$28 -> 240442.64 | E8: =E7+D8 -> 365805.52 | F8: ='C3 - BESS+Solar FP'!$C$23*(1-Premissas!$C$21)^(A8-1)*(1+Premissas!$C$42)^(A8-1)-'C3 - BESS+Solar FP'!$C$29 -> 486095.32 | G8: =G7+F8 -> 781516.21 | H8: ='C4 - Gerador Diesel'!$C$15*(1+Premissas!$C$42)^(A8-1)-'C4 - Gerador Diesel'!$C$16*(1+Premissas!$C$51)^(A8-1)-Premissas!$C$50 -> 112117.19 | I8: =I7+H8 -> 182591.28
A9: 5 | B9: ='C1 - BESS Puro'!$C$12*(1-Premissas!$C$21)^(A9-1)*(1+Premissas!$C$42)^(A9-1)-'C1 - BESS Puro'!$C$16 -> 208803.53 | C9: =C8+B9 -> 504208.46 | D9: ='C2 - BESS+Solar BESS'!$C$22*(1-Premissas!$C$21)^(A9-1)*(1+Premissas!$C$42)^(A9-1)-'C2 - BESS+Solar BESS'!$C$28 -> 252257.05 | E9: =E8+D9 -> 618062.57 | F9: ='C3 - BESS+Solar FP'!$C$23*(1-Premissas!$C$21)^(A9-1)*(1+Premissas!$C$42)^(A9-1)-'C3 - BESS+Solar FP'!$C$29 -> 509969.95 | G9: =G8+F9 -> 1291486.2 | H9: ='C4 - Gerador Diesel'!$C$15*(1+Premissas!$C$42)^(A9-1)-'C4 - Gerador Diesel'!$C$16*(1+Premissas!$C$51)^(A9-1)-Premissas!$C$50 -> 120665.39 | I9: =I8+H9 -> 303256.67
A10: 6 | B10: ='C1 - BESS Puro'!$C$12*(1-Premissas!$C$21)^(A10-1)*(1+Premissas!$C$42)^(A10-1)-'C1 - BESS Puro'!$C$16 -> 219059.86 | C10: =C9+B10 -> 723268.32 | D10: ='C2 - BESS+Solar BESS'!$C$22*(1-Premissas!$C$21)^(A10-1)*(1+Premissas!$C$42)^(A10-1)-'C2 - BESS+Solar BESS'!$C$28 -> 264645.63 | E10: =E9+D10 -> 882708.2 | F10: ='C3 - BESS+Solar FP'!$C$23*(1-Premissas!$C$21)^(A10-1)*(1+Premissas!$C$42)^(A10-1)-'C3 - BESS+Solar FP'!$C$29 -> 535004.88 | G10: =G9+F10 -> 1826491 | H10: ='C4 - Gerador Diesel'!$C$15*(1+Premissas!$C$42)^(A10-1)-'C4 - Gerador Diesel'!$C$16*(1+Premissas!$C$51)^(A10-1)-Premissas!$C$50 -> 129811.97 | I10: =I9+H10 -> 433068.63
A11: 7 | B11: ='C1 - BESS Puro'!$C$12*(1-Premissas!$C$21)^(A11-1)*(1+Premissas!$C$42)^(A11-1)-'C1 - BESS Puro'!$C$16 -> 229814.66 | C11: =C10+B11 -> 953082.98 | D11: ='C2 - BESS+Solar BESS'!$C$22*(1-Premissas!$C$21)^(A11-1)*(1+Premissas!$C$42)^(A11-1)-'C2 - BESS+Solar BESS'!$C$28 -> 277636.31 | E11: =E10+D11 -> 1160344.5 | F11: ='C3 - BESS+Solar FP'!$C$23*(1-Premissas!$C$21)^(A11-1)*(1+Premissas!$C$42)^(A11-1)-'C3 - BESS+Solar FP'!$C$29 -> 561256.52 | G11: =G10+F11 -> 2387747.6 | H11: ='C4 - Gerador Diesel'!$C$15*(1+Premissas!$C$42)^(A11-1)-'C4 - Gerador Diesel'!$C$16*(1+Premissas!$C$51)^(A11-1)-Premissas!$C$50 -> 139598.8 | I11: =I10+H11 -> 572667.44
A12: 8 | B12: ='C1 - BESS Puro'!$C$12*(1-Premissas!$C$21)^(A12-1)*(1+Premissas!$C$42)^(A12-1)-'C1 - BESS Puro'!$C$16 -> 241092.13 | C12: =C11+B12 -> 1194175.1 | D12: ='C2 - BESS+Solar BESS'!$C$22*(1-Premissas!$C$21)^(A12-1)*(1+Premissas!$C$42)^(A12-1)-'C2 - BESS+Solar BESS'!$C$28 -> 291258.32 | E12: =E11+D12 -> 1451602.8 | F12: ='C3 - BESS+Solar FP'!$C$23*(1-Premissas!$C$21)^(A12-1)*(1+Premissas!$C$42)^(A12-1)-'C3 - BESS+Solar FP'!$C$29 -> 588783.98 | G12: =G11+F12 -> 2976531.5 | H12: ='C4 - Gerador Diesel'!$C$15*(1+Premissas!$C$42)^(A12-1)-'C4 - Gerador Diesel'!$C$16*(1+Premissas!$C$51)^(A12-1)-Premissas!$C$50 -> 150070.72 | I12: =I11+H12 -> 722738.16
A13: 9 | B13: ='C1 - BESS Puro'!$C$12*(1-Premissas!$C$21)^(A13-1)*(1+Premissas!$C$42)^(A13-1)-'C1 - BESS Puro'!$C$16 -> 252917.69 | C13: =C12+B13 -> 1447092.8 | D13: ='C2 - BESS+Solar BESS'!$C$22*(1-Premissas!$C$21)^(A13-1)*(1+Premissas!$C$42)^(A13-1)-'C2 - BESS+Solar BESS'!$C$28 -> 305542.37 | E13: =E12+D13 -> 1757145.2 | F13: ='C3 - BESS+Solar FP'!$C$23*(1-Premissas!$C$21)^(A13-1)*(1+Premissas!$C$42)^(A13-1)-'C3 - BESS+Solar FP'!$C$29 -> 617649.27 | G13: =G12+F13 -> 3594180.8 | H13: ='C4 - Gerador Diesel'!$C$15*(1+Premissas!$C$42)^(A13-1)-'C4 - Gerador Diesel'!$C$16*(1+Premissas!$C$51)^(A13-1)-Premissas!$C$50 -> 161275.67 | I13: =I12+H13 -> 884013.83
A14: 10 | B14: ='C1 - BESS Puro'!$C$12*(1-Premissas!$C$21)^(A14-1)*(1+Premissas!$C$42)^(A14-1)-'C1 - BESS Puro'!$C$16 -> 265317.97 | C14: =C13+B14 -> 1712410.8 | D14: ='C2 - BESS+Solar BESS'!$C$22*(1-Premissas!$C$21)^(A14-1)*(1+Premissas!$C$42)^(A14-1)-'C2 - BESS+Solar BESS'!$C$28 -> 320520.63 | E14: =E13+D14 -> 2077665.8 | F14: ='C3 - BESS+Solar FP'!$C$23*(1-Premissas!$C$21)^(A14-1)*(1+Premissas!$C$42)^(A14-1)-'C3 - BESS+Solar FP'!$C$29 -> 647917.42 | G14: =G13+F14 -> 4242098.2 | H14: ='C4 - Gerador Diesel'!$C$15*(1+Premissas!$C$42)^(A14-1)-'C4 - Gerador Diesel'!$C$16*(1+Premissas!$C$51)^(A14-1)-Premissas!$C$50 -> 173264.97 | I14: =I13+H14 -> 1057278.8
A15: 11 | B15: ='C1 - BESS Puro'!$C$12*(1-Premissas!$C$21)^(A15-1)*(1+Premissas!$C$42)^(A15-1)-'C1 - BESS Puro'!$C$16 -> 278320.91 | C15: =C14+B15 -> 1990731.7 | D15: ='C2 - BESS+Solar BESS'!$C$22*(1-Premissas!$C$21)^(A15-1)*(1+Premissas!$C$42)^(A15-1)-'C2 - BESS+Solar BESS'!$C$28 -> 336226.82 | E15: =E14+D15 -> 2413892.7 | F15: ='C3 - BESS+Solar FP'!$C$23*(1-Premissas!$C$21)^(A15-1)*(1+Premissas!$C$42)^(A15-1)-'C3 - BESS+Solar FP'!$C$29 -> 679656.6 | G15: =G14+F15 -> 4921754.8 | H15: ='C4 - Gerador Diesel'!$C$15*(1+Premissas!$C$42)^(A15-1)-'C4 - Gerador Diesel'!$C$16*(1+Premissas!$C$51)^(A15-1)-Premissas!$C$50 -> 186093.52 | I15: =I14+H15 -> 1243372.3
A16: 12 | B16: ='C1 - BESS Puro'!$C$12*(1-Premissas!$C$21)^(A16-1)*(1+Premissas!$C$42)^(A16-1)-'C1 - BESS Puro'!$C$16 -> 291955.79 | C16: =C15+B16 -> 2282687.5 | D16: ='C2 - BESS+Solar BESS'!$C$22*(1-Premissas!$C$21)^(A16-1)*(1+Premissas!$C$42)^(A16-1)-'C2 - BESS+Solar BESS'!$C$28 -> 352696.34 | E16: =E15+D16 -> 2766589 | F16: ='C3 - BESS+Solar FP'!$C$23*(1-Premissas!$C$21)^(A16-1)*(1+Premissas!$C$42)^(A16-1)-'C3 - BESS+Solar FP'!$C$29 -> 712938.31 | G16: =G15+F16 -> 5634693.1 | H16: ='C4 - Gerador Diesel'!$C$15*(1+Premissas!$C$42)^(A16-1)-'C4 - Gerador Diesel'!$C$16*(1+Premissas!$C$51)^(A16-1)-Premissas!$C$50 -> 199820.06 | I16: =I15+H16 -> 1443192.4
A18: VPL (NPV) | B18: =NPV(Premissas!$C$41,B5:B16)+B4 -> 875432.4 | D18: =NPV(Premissas!$C$41,D5:D16)+D4 -> 1066515.2 | F18: =NPV(Premissas!$C$41,F5:F16)+F4 -> 2197969.6 | H18: =NPV(Premissas!$C$41,H5:H16)+H4 -> 559226.76
A19: TIR (IRR) | B19: =IFERROR(IRR(B4:B16),"—") -> 0.4254002 | D19: =IFERROR(IRR(D4:D16),"—") -> 0.43227977 | F19: =IFERROR(IRR(F4:F16),"—") -> 0.44915216 | H19: =IFERROR(IRR(H4:H16),"—") -> 0.47510196
