Workbook

Sheet Premissas
A1: DIMENSIONAMENTO — SISTEMA HÍBRIDO GRUPO B
A2: ● Azul = entrada do usuário ● Preto = fórmula ● Verde = referência de outra aba ● Amarelo = flag/premissa chave
A4: BLOCO 1 — DIMENSIONAMENTO DO INVERSOR
A5: Equipamento | B5: Pot. Unit. (W) | C5: Qtd | D5: Tipo de Carga | E5: Fator Partida | F5: Pot. Contínua (W) | G5: Pico (W)
A6: Iluminação LED | B6: 300 | C6: 5 | D6: Resistiva | E6: 1 | F6: =IFERROR(B6*C6,0) -> 1500 | G6: =IFERROR(B6*C6*E6,0) -> 1500
A7: Geladeira | B7: 300 | C7: 1 | D7: Indutiva | E7: 2 | F7: =IFERROR(B7*C7,0) -> 300 | G7: =IFERROR(B7*C7*E7,0) -> 600
A8: Ar-condicionado 9.000 BTU | B8: 300 | C8: 1 | D8: Indutiva | E8: 1 | F8: =IFERROR(B8*C8,0) -> 300 | G8: =IFERROR(B8*C8*E8,0) -> 300
A9: TV + Eletrônicos | B9: 300 | C9: 1 | D9: Eletrônica | E9: 1 | F9: =IFERROR(B9*C9,0) -> 300 | G9: =IFERROR(B9*C9*E9,0) -> 300
A10: Bomba d'água | B10: 300 | C10: 1 | D10: Indutiva | E10: 2 | F10: =IFERROR(B10*C10,0) -> 300 | G10: =IFERROR(B10*C10*E10,0) -> 600
E11: 1 | F11: =IFERROR(B11*C11,0) -> 0 | G11: =IFERROR(B11*C11*E11,0) -> 0
E12: 1 | F12: =IFERROR(B12*C12,0) -> 0 | G12: =IFERROR(B12*C12*E12,0) -> 0
E13: 1 | F13: =IFERROR(B13*C13,0) -> 0 | G13: =IFERROR(B13*C13*E13,0) -> 0
E14: 1 | F14: =IFERROR(B14*C14,0) -> 0 | G14: =IFERROR(B14*C14*E14,0) -> 0
E15: 1 | F15: =IFERROR(B15*C15,0) -> 0 | G15: =IFERROR(B15*C15*E15,0) -> 0
A17: Potência Contínua Total das Cargas (W) | B17: =IFERROR(SUM(F6:F15),0) -> 2700 | C17: W
A18: Pico de Partida Total (W) | B18: =IFERROR(SUM(G6:G15),0) -> 3300 | C18: W | D18: Soma de potência × fator de partida de todos os equipamentos
A20: Eficiência do Inversor (%) | B20: 0.95 | C20: %
A21: Margem de Segurança (%) | B21: 0.2 | C21: % | D21: Recomendado: mínimo 20%
A22: Faixa DC Mínima do Inversor (V) | B22: 40 | C22: V | D22: Verificar datasheet do inversor
A23: Faixa DC Máxima do Inversor (V) | B23: 60 | C23: V | D23: Verificar datasheet do inversor
A25: ➤ POTÊNCIA CONTÍNUA MÍNIMA DO INVERSOR (W) | B25: =IFERROR(B17/B20*(1+B21)/1000,0) -> 3.4105263 | C25: kW | D25: Pot.contínua ÷ eficiência × (1 + margem)
A26: ➤ POTÊNCIA DE PICO MÍNIMA DO INVERSOR (W) | B26: =IFERROR(B18/B20*(1+B21)/1000,0) -> 4.1684211 | C26: kW | D26: Pico de partida ÷ eficiência × (1 + margem)
A28: BLOCO 2 — DIMENSIONAMENTO DAS BATERIAS
A29: Especificações da Bateria Unitária
A30: Tensão Nominal do Banco de Baterias (V) | B30: 48 | C30: V | D30: Deve estar dentro da faixa DC do inversor
A31: Tensão Nominal da Bateria Unitária (V) | B31: 48 | C31: V
A32: Capacidade da Bateria Unitária (Ah) | B32: 100 | C32: Ah
A33: Capacidade da Bateria Unitária (kWh) | B33: =IFERROR(B31*B32/1000,0) -> 4.8 | C33: kWh | D33: Calculado automaticamente
A34: Corrente Máxima de Descarga — Bateria Unit. (A) | B34: 100 | C34: A
A36: Parâmetros de Operação
A37: DoD — Profundidade de Descarga (%) | B37: 0.9 | C37: % | D37: LFP: até 80-90% · Chumbo-ácido: até 50%
A38: Eficiência (%) | B38: 0.91 | C38: % | D38: Round-trip LFP: 90-95%. Inclui perdas ôhmicas, eletroquímicas, BMS e térmicas.
A39: Autonomia Desejada (horas) | B39: 4 | C39: h | D39: Definir com o cliente
A41: Cálculo do Banco
A42: Potência das Cargas Essenciais (W) | B42: =B17 -> 2700 | C42: W | D42: Referência do Bloco 1
A43: Energia Necessária por Ciclo (kWh) | B43: =IFERROR(B42/1000*B39,0) -> 10.8 | C43: kWh | D43: Potência × Autonomia
A44: Capacidade Nominal Necessária (kWh) | B44: =IFERROR(B43/B37/B38,0) -> 13.186813 | C44: kWh | D44: Considerando DoD, eficiência e temperatura
A45: Capacidade Necessária em Ah (na tensão do banco) | B45: =IFERROR(B44*1000/B30,0) -> 274.72527 | C45: Ah
A46: Número de Baterias em Série | B46: =IFERROR(ROUND(B30/B31,0),1) -> 1 | C46: un. | D46: Para compor a tensão do banco
A47: Número de Baterias em Paralelo | B47: =IFERROR(MAX(1,CEILING(B45/B32,1)),1) -> 3 | C47: un. | D47: Para compor a capacidade em Ah
...

Sheet Financeiro
A1: FINANCEIRO — CAPEX E PREMISSAS FINANCEIRAS
A2: ● Azul = entrada do usuário ● Preto = fórmula ● Verde = referência de outra aba ● Amarelo = flag/premissa chave
A4: CAPEX DO SISTEMA
A5: Modo de entrada do CAPEX | B5: Simplificado | D5: Simplificado: R$/kWp | Detalhado: itemizado
A7: Modo Simplificado (R$/kWh de armazenamento)
A8: Custo por kWh de Armazenamento (R$/kWh) | B8: 2500 | C8: R$/kWh | D8: Inclui baterias, inversor, instalação e outros
A9: Capacidade Real Instalada (kWh) | B9: =Premissas!B49 -> 14.4 | C9: kWh
A10: Potência FV Instalada (kWp) | B10: =Premissas!B86 -> 5.45 | C10: kWp | D10: Apenas informativo — não entra no cálculo simplificado
A11: CAPEX Simplificado (R$) | B11: =IFERROR(B8*B9,0) -> 36000 | C11: R$
A13: Modo Detalhado (itemizado)
A14: Preço do Inversor Híbrido (R$) | B14: 8000 | C14: R$
A15: Preço das Baterias — Total (R$) | B15: 12000 | C15: R$ | D15: Nº de baterias × preço unitário
A16: Instalação e Mão de Obra (R$) | B16: 3500 | C16: R$
A17: Outros (estrutura, cabeamento, proteções) (R$) | B17: 1500 | C17: R$
A18: CAPEX Detalhado (R$) | B18: =IFERROR(B14+B15+B16+B17,0) -> 25000 | C18: R$
A20: ➤ CAPEX TOTAL (R$) | B20: =IFERROR(IF(B5="Simplificado",B11,B18),0) -> 36000 | C20: R$
A22: PREMISSAS FINANCEIRAS
A23: Horizonte de Análise (anos) | B23: 24 | C23: anos | D23: 12 anos: ciclo padrão | 24 anos: inclui reposição de bateria
A24: Taxa de Reajuste Tarifário Anual (%) | B24: 0.1 | C24: % | D24: Histórico ANEEL: 5-10% a.a.
A25: Taxa Mínima de Atratividade — TMA (%) | B25: 0.12 | C25: % | D25: Custo de capital do investidor
A26: O&M Anual (% do CAPEX) | B26: 0.005 | C26: % | D26: Manutenção, seguros, monitoramento
A27: Degradação Anual da Bateria (%) | B27: 0.02 | C27: % | D27: Redução de capacidade por ano
A28: Custo de Reposição da Bateria (R$) | B28: 12000 | C28: R$ | D28: Aplicado no ano 13 no horizonte de 25 anos
A29: Ano da Reposição da Bateria | B29: 13 | C29: ano | D29: Vida útil típica LFP: 10-15 anos
A30: Inflação Anual (%) | B30: 0.04 | C30: % | D30: Para atualizar O&M e custos operacionais

Sheet C1 — Backup
A1: CENÁRIO 1 — BACKUP PURO
A2: ● Azul = entrada do usuário ● Preto = fórmula ● Verde = referência de outra aba ● Amarelo = flag/premissa chave
A4: ESPECIFICAÇÕES DO SISTEMA
A5: Potência das Cargas Essenciais (W) | B5: =Premissas!B17 -> 2700 | C5: W
A6: Capacidade Utilizável do Banco (kWh) | B6: =Premissas!B50 -> 11.7936 | C6: kWh
A7: Número Total de Baterias | B7: =Premissas!B48 -> 3 | C7: un.
A8: Autonomia Real (horas) | B8: =IFERROR(Premissas!B50/(Premissas!B17/1000),0) -> 4.368 | C8: h | D8: Capacidade utilizável ÷ potência das cargas
A10: CAPEX DO SISTEMA
A11: CAPEX Total (R$) | B11: =Financeiro!B20 -> 36000 | C11: R$
A13: OBSERVAÇÃO
A14: O Cenário 1 é backup puro — não gera economia na conta de energia. O valor para o cliente é a continuidade de fornecimento durante quedas de rede. O payback é qualitativo (depende de quanto o cliente valoriza a continuidade).

Sheet C2 — Arbitragem
A1: CENÁRIO 2 — ARBITRAGEM TARIFÁRIA (SEM FV) — TARIFA BRANCA
A2: ● Azul = entrada do usuário ● Preto = fórmula ● Verde = referência de outra aba ● Amarelo = flag/premissa chave
A4: DADOS DO SISTEMA (Premissas)
A5: Capacidade Utilizável do Banco (kWh) | B5: =Premissas!B50 -> 11.7936 | C5: kWh
A6: Eficiência Round-Trip (%) | B6: =Premissas!B38 -> 0.91 | C6: %
A7: Tarifa na Ponta (R$/kWh) | B7: =Premissas!B68 -> 1.4 | C7: R$/kWh
A8: Tarifa Fora Ponta (R$/kWh) | B8: =Premissas!B69 -> 0.44 | C8: R$/kWh
A9: Consumo na Ponta (kWh/mês) | B9: =Premissas!B71 -> 500 | C9: kWh/mês
A10: Fio B (R$/kWh) | B10: =Premissas!B76 -> 0.29 | C10: R$/kWh
A11: ICMS (%) | B11: =Premissas!B75 -> 0.18 | C11: %
A13: CÁLCULO DE ENERGIA DESLOCADA
A14: Energia Disponível por Ciclo (kWh) — descarga | B14: =B5 -> 11.7936 | C14: kWh | D14: Energia que o banco fornece por ciclo completo
A15: Dias Úteis no Mês com Ponta | B15: 30 | C15: dias | D15: Número de dias com horário de ponta no mês
A16: Energia Deslocada por Mês (kWh) | B16: =IFERROR(MIN(B14*B15,B9),0) -> 353.808 | C16: kWh/mês | D16: Limitado ao consumo real na ponta
A17: Energia para Recarga do Banco (kWh) — fora ponta | B17: =IFERROR(B16/B6,0) -> 388.8 | C17: kWh/mês | D17: Energia consumida da rede no FP para carregar
A19: CÁLCULO DE ECONOMIA
A20: Economia Bruta — Evitar Ponta (R$) | B20: =IFERROR(B16*B7,0) -> 495.3312 | C20: R$/mês | D20: Deixa de consumir kWh da ponta
A21: Custo da Recarga — Fora Ponta (R$) | B21: =IFERROR(B17*B8,0) -> 171.072 | C21: R$/mês | D21: Paga para carregar o banco no fora ponta
A22: Economia Líquida de Arbitragem (R$) | B22: =IFERROR(B20-B21,0) -> 324.2592 | C22: R$/mês
A24: Nota: Fio B e ICMS na Arbitragem
A25: Na arbitragem, quando a bateria descarga e o cliente deixa de consumir da rede na ponta, ele economiza a tarifa ponta COMPLETA (incluindo Fio B e ICMS). Quando recarrega no fora ponta, paga a tarifa fora ponta completa. O cálculo acima já captura corretamente essa diferença sem necessidade de ajuste adicional.
A29: ANÁLISE ECONÔMICA (referência — Comparativo tem análise completa)
A30: Economia Líquida Mensal (R$) | B30: =B22 -> 324.2592 | C30: R$/mês
A31: Economia Líquida Anual — Ano 1 (R$) | B31: =IFERROR(B30*12,0) -> 3891.1104 | C31: R$/ano
A32: CAPEX Total (R$) | B32: =Financeiro!B20 -> 36000 | C32: R$
A33: Payback Simples (anos) | B33: =IFERROR(Financeiro!B20/B31,0) -> 9.2518578 | C33: anos

Sheet C3 — Arbitragem + FV
A1: CENÁRIO 3 — ARBITRAGEM + FV — TARIFA BRANCA
A2: ● Azul = entrada do usuário ● Preto = fórmula ● Verde = referência de outra aba ● Amarelo = flag/premissa chave
A4: DADOS DO SISTEMA (Premissas)
A5: FV Ativo? | B5: =Premissas!B84 -> Sim
A6: Geração Total FV (kWh/mês) | B6: =Premissas!B88 -> 654 | C6: kWh/mês
A7: Autoconsumo Direto (kWh/mês) | B7: =Premissas!B90 -> 261.6 | C7: kWh/mês | D7: Simultaneidade — não passa pela rede
A8: Energia FV → Bateria (kWh/mês) | B8: =Premissas!B92 -> 353.808 | C8: kWh/mês
A9: Energia FV Injetada na Rede (kWh/mês) | B9: =Premissas!B94 -> 38.592 | C9: kWh/mês | D9: Paga Fio B e ICMS quando compensada
A10: Capacidade Utilizável do Banco (kWh) | B10: =Premissas!B50 -> 11.7936 | C10: kWh
A11: Tarifa Ponta (R$/kWh) | B11: =Premissas!B68 -> 1.4 | C11: R$/kWh
A12: Tarifa Fora Ponta (R$/kWh) | B12: =Premissas!B69 -> 0.44 | C12: R$/kWh
A13: Tarifa Compensável Ponta (R$/kWh) | B13: =Premissas!B80 -> 1.0817073 | C13: R$/kWh | D13: TE compensável, sem Fio B e sem ICMS
A14: Tarifa Compensável Fora Ponta (R$/kWh) | B14: =Premissas!B81 -> 0.12170732 | C14: R$/kWh
A15: Fio B (R$/kWh) | B15: =Premissas!B76 -> 0.29 | C15: R$/kWh
A16: Eficiência Round-Trip (%) | B16: =Premissas!B38 -> 0.91 | C16: %
A17: Consumo na Ponta (kWh/mês) | B17: =Premissas!B71 -> 500 | C17: kWh/mês
A18: Dias Úteis no Mês | B18: 22 | C18: dias
A20: CÁLCULO DE ECONOMIA
A21: Economia — Autoconsumo Direto FV (R$) | B21: =IFERROR(B7*B12,0) -> 115.104 | C21: R$/mês | D21: kWh consumidos diretamente × tarifa fora ponta (evitado)
A22: Energia Bateria Descarregada na Ponta (kWh) | B22: =IFERROR(MIN(B10*30,B17),0) -> 353.808 | C22: kWh/mês | D22: Bateria sempre descarrega na ponta — limitado ao consumo
A23: Economia — FV via Bateria na Ponta (R$) | B23: =IFERROR(B22*B11,0) -> 495.3312 | C23: R$/mês | D23: Evita consumo da ponta — tarifa ponta completa economizada
A24: Economia Bruta — Compensação FV (R$) | B24: =IFERROR(B9*B12,0) -> 16.98048 | C24: R$/mês
A25: Custo Fio B sobre Energia Compensada (R$) | B25: =IFERROR(B9*B15,0) -> 11.19168 | C25: R$/mês | D25: Fio B não é compensado — pago sobre kWh compensados
A26: Custo ICMS sobre Energia Compensada (R$) | B26: =IFERROR(B9*B12*(Premissas!B75),0) -> 3.0564864 | C26: R$/mês | D26: ICMS não é compensado — pago sobre kWh compensados
A27: Economia Líquida — Compensação FV (R$) | B27: =IFERROR(B9*B14,0) -> 4.6969288 | C27: R$/mês | D27: Tarifa compensável × kWh injetados
A28: Energia da Rede → Bateria (kWh/mês) | B28: =IFERROR(Premissas!B93,0) -> 0 | C28: kWh/mês | D28: Rede completa a bateria no FP quando FV não basta
A29: Custo da Recarga Complementar da Rede (R$) | B29: =IFERROR(Premissas!B95*B12,0) -> 0 | C29: R$/mês | D29: Recarga bruta (com perda de eficiência) × tarifa FP
A30: Economia — Arbitragem Complementar (R$) | B30: =IFERROR(B28*B11-B29,0) -> 0 | C30: R$/mês | D30: Economia: desloca ponta menos custo de recarga FP
A32: ECONOMIA LÍQUIDA TOTAL (R$/mês) | B32: =IFERROR(B21+B23+B27+B30,0) -> 615.13213 | C32: R$/mês
A34: ANÁLISE ECONÔMICA (referência — Comparativo tem análise completa)
A35: Economia Líquida Mensal (R$) | B35: =B32 -> 615.13213 | C35: R$/mês
A36: Economia Líquida Anual — Ano 1 (R$) | B36: =IFERROR(B35*12,0) -> 7381.5855 | C36: R$/ano
A37: CAPEX Total (R$) | B37: =Financeiro!B20 -> 36000 | C37: R$
A38: Payback Simples (anos) | B38: =IFERROR(Financeiro!B20/B36,0) -> 4.877001 | C38: anos

Sheet Comparativo
A1: COMPARATIVO DE CENÁRIOS — FLUXO DE CAIXA E ANÁLISE FINANCEIRA
A2: ● Azul = entrada do usuário ● Preto = fórmula ● Verde = referência de outra aba ● Amarelo = flag/premissa chave
B3: Ano 0 | C3: =IF(1>VALUE(Financeiro!$B$23),"","Ano 1") -> Ano 1 | D3: =IF(2>VALUE(Financeiro!$B$23),"","Ano 2") -> Ano 2 | E3: =IF(3>VALUE(Financeiro!$B$23),"","Ano 3") -> Ano 3 | F3: =IF(4>VALUE(Financeiro!$B$23),"","Ano 4") -> Ano 4 | G3: =IF(5>VALUE(Financeiro!$B$23),"","Ano 5") -> Ano 5 | H3: =IF(6>VALUE(Financeiro!$B$23),"","Ano 6") -> Ano 6 | I3: =IF(7>VALUE(Financeiro!$B$23),"","Ano 7") -> Ano 7 | J3: =IF(8>VALUE(Financeiro!$B$23),"","Ano 8") -> Ano 8 | K3: =IF(9>VALUE(Financeiro!$B$23),"","Ano 9") -> Ano 9 | L3: =IF(10>VALUE(Financeiro!$B$23),"","Ano 10") -> Ano 10 | M3: =IF(11>VALUE(Financeiro!$B$23),"","Ano 11") -> Ano 11 | N3: =IF(12>VALUE(Financeiro!$B$23),"","Ano 12") -> Ano 12 | O3: =IF(13>VALUE(Financeiro!$B$23),"","Ano 13") -> Ano 13 | P3: =IF(14>VALUE(Financeiro!$B$23),"","Ano 14") -> Ano 14 | Q3: =IF(15>VALUE(Financeiro!$B$23),"","Ano 15") -> Ano 15 | R3: =IF(16>VALUE(Financeiro!$B$23),"","Ano 16") -> Ano 16 | S3: =IF(17>VALUE(Financeiro!$B$23),"","Ano 17") -> Ano 17 | T3: =IF(18>VALUE(Financeiro!$B$23),"","Ano 18") -> Ano 18 | U3: =IF(19>VALUE(Financeiro!$B$23),"","Ano 19") -> Ano 19 | V3: =IF(20>VALUE(Financeiro!$B$23),"","Ano 20") -> Ano 20 | W3: =IF(21>VALUE(Financeiro!$B$23),"","Ano 21") -> Ano 21 | X3: =IF(22>VALUE(Financeiro!$B$23),"","Ano 22") -> Ano 22 | Y3: =IF(23>VALUE(Financeiro!$B$23),"","Ano 23") -> Ano 23 | Z3: =IF(24>VALUE(Financeiro!$B$23),"","Ano 24") -> Ano 24 | AA3: =IF(25>VALUE(Financeiro!$B$23),"","Ano 25")
A4: CENÁRIO 2 — ARBITRAGEM TARIFÁRIA (SEM FV)
A5: CAPEX Inicial (R$) | B5: =-Financeiro!B20 -> -36000 | C5: 0 | D5: 0 | E5: 0 | F5: 0 | G5: 0 | H5: 0 | I5: 0 | J5: 0 | K5: 0 | L5: 0 | M5: 0 | N5: 0 | O5: 0 | P5: 0 | Q5: 0 | R5: 0 | S5: 0 | T5: 0 | U5: 0 | V5: 0 | W5: 0 | X5: 0 | Y5: 0 | Z5: 0 | AA5: 0
A6: Economia Anual (R$) | B6: 0 | C6: =IF(1>VALUE(Financeiro!$B$23),"",IFERROR('C2 — Arbitragem'!B31*(1+Financeiro!B24)^1,0)) -> 4280.2214 | D6: =IF(2>VALUE(Financeiro!$B$23),"",IFERROR('C2 — Arbitragem'!B31*(1+Financeiro!B24)^2,0)) -> 4708.2436 | E6: =IF(3>VALUE(Financeiro!$B$23),"",IFERROR('C2 — Arbitragem'!B31*(1+Financeiro!B24)^3,0)) -> 5179.0679 | F6: =IF(4>VALUE(Financeiro!$B$23),"",IFERROR('C2 — Arbitragem'!B31*(1+Financeiro!B24)^4,0)) -> 5696.9747 | G6: =IF(5>VALUE(Financeiro!$B$23),"",IFERROR('C2 — Arbitragem'!B31*(1+Financeiro!B24)^5,0)) -> 6266.6722 | H6: =IF(6>VALUE(Financeiro!$B$23),"",IFERROR('C2 — Arbitragem'!B31*(1+Financeiro!B24)^6,0)) -> 6893.3394 | I6: =IF(7>VALUE(Financeiro!$B$23),"",IFERROR('C2 — Arbitragem'!B31*(1+Financeiro!B24)^7,0)) -> 7582.6734 | J6: =IF(8>VALUE(Financeiro!$B$23),"",IFERROR('C2 — Arbitragem'!B31*(1+Financeiro!B24)^8,0)) -> 8340.9407 | K6: =IF(9>VALUE(Financeiro!$B$23),"",IFERROR('C2 — Arbitragem'!B31*(1+Financeiro!B24)^9,0)) -> 9175.0348 | L6: =IF(10>VALUE(Financeiro!$B$23),"",IFERROR('C2 — Arbitragem'!B31*(1+Financeiro!B24)^10,0)) -> 10092.538 | M6: =IF(11>VALUE(Financeiro!$B$23),"",IFERROR('C2 — Arbitragem'!B31*(1+Financeiro!B24)^11,0)) -> 11101.792 | N6: =IF(12>VALUE(Financeiro!$B$23),"",IFERROR('C2 — Arbitragem'!B31*(1+Financeiro!B24)^12,0)) -> 12211.971 | O6: =IF(13>VALUE(Financeiro!$B$23),"",IFERROR('C2 — Arbitragem'!B31*(1+Financeiro!B24)^13,0)) -> 13433.168 | P6: =IF(14>VALUE(Financeiro!$B$23),"",IFERROR('C2 — Arbitragem'!B31*(1+Financeiro!B24)^14,0)) -> 14776.485 | Q6: =IF(15>VALUE(Financeiro!$B$23),"",IFERROR('C2 — Arbitragem'!B31*(1+Financeiro!B24)^15,0)) -> 16254.134 | R6: =IF(16>VALUE(Financeiro!$B$23),"",IFERROR('C2 — Arbitragem'!B31*(1+Financeiro!B24)^16,0)) -> 17879.547 | S6: =IF(17>VALUE(Financeiro!$B$23),"",IFERROR('C2 — Arbitragem'!B31*(1+Financeiro!B24)^17,0)) -> 19667.502 | T6: =IF(18>VALUE(Financeiro!$B$23),"",IFERROR('C2 — Arbitragem'!B31*(1+Financeiro!B24)^18,0)) -> 21634.252 | U6: =IF(19>VALUE(Financeiro!$B$23),"",IFERROR('C2 — Arbitragem'!B31*(1+Financeiro!B24)^19,0)) -> 23797.677 | V6: =IF(20>VALUE(Financeiro!$B$23),"",IFERROR('C2 — Arbitragem'!B31*(1+Financeiro!B24)^20,0)) -> 26177.445 | W6: =IF(21>VALUE(Financeiro!$B$23),"",IFERROR('C2 — Arbitragem'!B31*(1+Financeiro!B24)^21,0)) -> 28795.19 | X6: =IF(22>VALUE(Financeiro!$B$23),"",IFERROR('C2 — Arbitragem'!B31*(1+Financeiro!B24)^22,0)) -> 31674.708 | Y6: =IF(23>VALUE(Financeiro!$B$23),"",IFERROR('C2 — Arbitragem'!B31*(1+Financeiro!B24)^23,0)) -> 34842.179 | Z6: =IF(24>VALUE(Financeiro!$B$23),"",IFERROR('C2 — Arbitragem'!B31*(1+Financeiro!B24)^24,0)) -> 38326.397 | AA6: =IF(25>VALUE(Financeiro!$B$23),"",IFERROR('C2 — Arbitragem'!B31*(1+Financeiro!B24)^25,0))
A7: O&M Anual (R$) | B7: 0 | C7: =IF(1>VALUE(Financeiro!$B$23),"",IFERROR(-Financeiro!B20*(Financeiro!B26)*(1+Financeiro!B30)^1,0)) -> -187.2 | D7: =IF(2>VALUE(Financeiro!$B$23),"",IFERROR(-Financeiro!B20*(Financeiro!B26)*(1+Financeiro!B30)^2,0)) -> -194.688 | E7: =IF(3>VALUE(Financeiro!$B$23),"",IFERROR(-Financeiro!B20*(Financeiro!B26)*(1+Financeiro!B30)^3,0)) -> -202.47552 | F7: =IF(4>VALUE(Financeiro!$B$23),"",IFERROR(-Financeiro!B20*(Financeiro!B26)*(1+Financeiro!B30)^4,0)) -> -210.57454 | G7: =IF(5>VALUE(Financeiro!$B$23),"",IFERROR(-Financeiro!B20*(Financeiro!B26)*(1+Financeiro!B30)^5,0)) -> -218.99752 | H7: =IF(6>VALUE(Financeiro!$B$23),"",IFERROR(-Financeiro!B20*(Financeiro!B26)*(1+Financeiro!B30)^6,0)) -> -227.75742 | I7: =IF(7>VALUE(Financeiro!$B$23),"",IFERROR(-Financeiro!B20*(Financeiro!B26)*(1+Financeiro!B30)^7,0)) -> -236.86772 | J7: =IF(8>VALUE(Financeiro!$B$23),"",IFERROR(-Financeiro!B20*(Financeiro!B26)*(1+Financeiro!B30)^8,0)) -> -246.34243 | K7: =IF(9>VALUE(Financeiro!$B$23),"",IFERROR(-Financeiro!B20*(Financeiro!B26)*(1+Financeiro!B30)^9,0)) -> -256.19613 | L7: =IF(10>VALUE(Financeiro!$B$23),"",IFERROR(-Financeiro!B20*(Financeiro!B26)*(1+Financeiro!B30)^10,0)) -> -266.44397 | M7: =IF(11>VALUE(Financeiro!$B$23),"",IFERROR(-Financeiro!B20*(Financeiro!B26)*(1+Financeiro!B30)^11,0)) -> -277.10173 | N7: =IF(12>VALUE(Financeiro!$B$23),"",IFERROR(-Financeiro!B20*(Financeiro!B26)*(1+Financeiro!B30)^12,0)) -> -288.1858 | O7: =IF(13>VALUE(Financeiro!$B$23),"",IFERROR(-Financeiro!B20*(Financeiro!B26)*(1+Financeiro!B30)^13,0)) -> -299.71323 | P7: =IF(14>VALUE(Financeiro!$B$23),"",IFERROR(-Financeiro!B20*(Financeiro!B26)*(1+Financeiro!B30)^14,0)) -> -311.70176 | Q7: =IF(15>VALUE(Financeiro!$B$23),"",IFERROR(-Financeiro!B20*(Financeiro!B26)*(1+Financeiro!B30)^15,0)) -> -324.16983 | R7: =IF(16>VALUE(Financeiro!$B$23),"",IFERROR(-Financeiro!B20*(Financeiro!B26)*(1+Financeiro!B30)^16,0)) -> -337.13662 | S7: =IF(17>VALUE(Financeiro!$B$23),"",IFERROR(-Financeiro!B20*(Financeiro!B26)*(1+Financeiro!B30)^17,0)) -> -350.62209 | T7: =IF(18>VALUE(Financeiro!$B$23),"",IFERROR(-Financeiro!B20*(Financeiro!B26)*(1+Financeiro!B30)^18,0)) -> -364.64697 | U7: =IF(19>VALUE(Financeiro!$B$23),"",IFERROR(-Financeiro!B20*(Financeiro!B26)*(1+Financeiro!B30)^19,0)) -> -379.23285 | V7: =IF(20>VALUE(Financeiro!$B$23),"",IFERROR(-Financeiro!B20*(Financeiro!B26)*(1+Financeiro!B30)^20,0)) -> -394.40217 | W7: =IF(21>VALUE(Financeiro!$B$23),"",IFERROR(-Financeiro!B20*(Financeiro!B26)*(1+Financeiro!B30)^21,0)) -> -410.17825 | X7: =IF(22>VALUE(Financeiro!$B$23),"",IFERROR(-Financeiro!B20*(Financeiro!B26)*(1+Financeiro!B30)^22,0)) -> -426.58538 | Y7: =IF(23>VALUE(Financeiro!$B$23),"",IFERROR(-Financeiro!B20*(Financeiro!B26)*(1+Financeiro!B30)^23,0)) -> -443.6488 | Z7: =IF(24>VALUE(Financeiro!$B$23),"",IFERROR(-Financeiro!B20*(Financeiro!B26)*(1+Financeiro!B30)^24,0)) -> -461.39475 | AA7: =IF(25>VALUE(Financeiro!$B$23),"",IFERROR(-Financeiro!B20*(Financeiro!B26)*(1+Financeiro!B30)^25,0))
A8: Fluxo Líquido (R$) | B8: =-Financeiro!B20 -> -36000 | C8: =IF(1>VALUE(Financeiro!$B$23),"",IFERROR(C6+C7,0)) -> 4093.0214 | D8: =IF(2>VALUE(Financeiro!$B$23),"",IFERROR(D6+D7,0)) -> 4513.5556 | E8: =IF(3>VALUE(Financeiro!$B$23),"",IFERROR(E6+E7,0)) -> 4976.5924 | F8: =IF(4>VALUE(Financeiro!$B$23),"",IFERROR(F6+F7,0)) -> 5486.4002 | G8: =IF(5>VALUE(Financeiro!$B$23),"",IFERROR(G6+G7,0)) -> 6047.6747 | H8: =IF(6>VALUE(Financeiro!$B$23),"",IFERROR(H6+H7,0)) -> 6665.582 | I8: =IF(7>VALUE(Financeiro!$B$23),"",IFERROR(I6+I7,0)) -> 7345.8057 | J8: =IF(8>VALUE(Financeiro!$B$23),"",IFERROR(J6+J7,0)) -> 8094.5983 | K8: =IF(9>VALUE(Financeiro!$B$23),"",IFERROR(K6+K7,0)) -> 8918.8387 | L8: =IF(10>VALUE(Financeiro!$B$23),"",IFERROR(L6+L7,0)) -> 9826.0943 | M8: =IF(11>VALUE(Financeiro!$B$23),"",IFERROR(M6+M7,0)) -> 10824.69 | N8: =IF(12>VALUE(Financeiro!$B$23),"",IFERROR(N6+N7,0)) -> 11923.785 | O8: =IF(13>VALUE(Financeiro!$B$23),"",IFERROR(O6+O7,0)) -> 13133.455 | P8: =IF(14>VALUE(Financeiro!$B$23),"",IFERROR(P6+P7,0)) -> 14464.784 | Q8: =IF(15>VALUE(Financeiro!$B$23),"",IFERROR(Q6+Q7,0)) -> 15929.964 | R8: =IF(16>VALUE(Financeiro!$B$23),"",IFERROR(R6+R7,0)) -> 17542.411 | S8: =IF(17>VALUE(Financeiro!$B$23),"",IFERROR(S6+S7,0)) -> 19316.88 | T8: =IF(18>VALUE(Financeiro!$B$23),"",IFERROR(T6+T7,0)) -> 21269.605 | U8: =IF(19>VALUE(Financeiro!$B$23),"",IFERROR(U6+U7,0)) -> 23418.444 | V8: =IF(20>VALUE(Financeiro!$B$23),"",IFERROR(V6+V7,0)) -> 25783.043 | W8: =IF(21>VALUE(Financeiro!$B$23),"",IFERROR(W6+W7,0)) -> 28385.011 | X8: =IF(22>VALUE(Financeiro!$B$23),"",IFERROR(X6+X7,0)) -> 31248.123 | Y8: =IF(23>VALUE(Financeiro!$B$23),"",IFERROR(Y6+Y7,0)) -> 34398.531 | Z8: =IF(24>VALUE(Financeiro!$B$23),"",IFERROR(Z6+Z7,0)) -> 37865.003 | AA8: =IF(25>VALUE(Financeiro!$B$23),"",IFERROR(AA6+AA7,0))
A9: Fluxo Acumulado (R$) | B9: =-Financeiro!B20 -> -36000 | C9: =IF(1>VALUE(Financeiro!$B$23),"",IFERROR(B9+C8,0)) -> -31906.979 | D9: =IF(2>VALUE(Financeiro!$B$23),"",IFERROR(C9+D8,0)) -> -27393.423 | E9: =IF(3>VALUE(Financeiro!$B$23),"",IFERROR(D9+E8,0)) -> -22416.831 | F9: =IF(4>VALUE(Financeiro!$B$23),"",IFERROR(E9+F8,0)) -> -16930.43 | G9: =IF(5>VALUE(Financeiro!$B$23),"",IFERROR(F9+G8,0)) -> -10882.756 | H9: =IF(6>VALUE(Financeiro!$B$23),"",IFERROR(G9+H8,0)) -> -4217.1737 | I9: =IF(7>VALUE(Financeiro!$B$23),"",IFERROR(H9+I8,0)) -> 3128.632 | J9: =IF(8>VALUE(Financeiro!$B$23),"",IFERROR(I9+J8,0)) -> 11223.23 | K9: =IF(9>VALUE(Financeiro!$B$23),"",IFERROR(J9+K8,0)) -> 20142.069 | L9: =IF(10>VALUE(Financeiro!$B$23),"",IFERROR(K9+L8,0)) -> 29968.163 | M9: =IF(11>VALUE(Financeiro!$B$23),"",IFERROR(L9+M8,0)) -> 40792.854 | N9: =IF(12>VALUE(Financeiro!$B$23),"",IFERROR(M9+N8,0)) -> 52716.639 | O9: =IF(13>VALUE(Financeiro!$B$23),"",IFERROR(N9+O8,0)) -> 65850.094 | P9: =IF(14>VALUE(Financeiro!$B$23),"",IFERROR(O9+P8,0)) -> 80314.878 | Q9: =IF(15>VALUE(Financeiro!$B$23),"",IFERROR(P9+Q8,0)) -> 96244.842 | R9: =IF(16>VALUE(Financeiro!$B$23),"",IFERROR(Q9+R8,0)) -> 113787.25 | S9: =IF(17>VALUE(Financeiro!$B$23),"",IFERROR(R9+S8,0)) -> 133104.13 | T9: =IF(18>VALUE(Financeiro!$B$23),"",IFERROR(S9+T8,0)) -> 154373.74 | U9: =IF(19>VALUE(Financeiro!$B$23),"",IFERROR(T9+U8,0)) -> 177792.18 | V9: =IF(20>VALUE(Financeiro!$B$23),"",IFERROR(U9+V8,0)) -> 203575.22 | W9: =IF(21>VALUE(Financeiro!$B$23),"",IFERROR(V9+W8,0)) -> 231960.24 | X9: =IF(22>VALUE(Financeiro!$B$23),"",IFERROR(W9+X8,0)) -> 263208.36 | Y9: =IF(23>VALUE(Financeiro!$B$23),"",IFERROR(X9+Y8,0)) -> 297606.89 | Z9: =IF(24>VALUE(Financeiro!$B$23),"",IFERROR(Y9+Z8,0)) -> 335471.89 | AA9: =IF(25>VALUE(Financeiro!$B$23),"",IFERROR(Z9+AA8,0))
A10: Fluxo Descontado (R$) | B10: =-Financeiro!B20 -> -36000 | C10: =IF(1>VALUE(Financeiro!$B$23),"",IFERROR(C8/(1+Financeiro!B25)^1,0)) -> 3654.4834 | D10: =IF(2>VALUE(Financeiro!$B$23),"",IFERROR(D8/(1+Financeiro!B25)^2,0)) -> 3598.1789 | E10: =IF(3>VALUE(Financeiro!$B$23),"",IFERROR(E8/(1+Financeiro!B25)^3,0)) -> 3542.2402 | F10: =IF(4>VALUE(Financeiro!$B$23),"",IFERROR(F8/(1+Financeiro!B25)^4,0)) -> 3486.7065 | G10: =IF(5>VALUE(Financeiro!$B$23),"",IFERROR(G8/(1+Financeiro!B25)^5,0)) -> 3431.613 | H10: =IF(6>VALUE(Financeiro!$B$23),"",IFERROR(H8/(1+Financeiro!B25)^6,0)) -> 3376.9913 | I10: =IF(7>VALUE(Financeiro!$B$23),"",IFERROR(I8/(1+Financeiro!B25)^7,0)) -> 3322.8694 | J10: =IF(8>VALUE(Financeiro!$B$23),"",IFERROR(J8/(1+Financeiro!B25)^8,0)) -> 3269.2725 | K10: =IF(9>VALUE(Financeiro!$B$23),"",IFERROR(K8/(1+Financeiro!B25)^9,0)) -> 3216.2226 | L10: =IF(10>VALUE(Financeiro!$B$23),"",IFERROR(L8/(1+Financeiro!B25)^10,0)) -> 3163.7394 | M10: =IF(11>VALUE(Financeiro!$B$23),"",IFERROR(M8/(1+Financeiro!B25)^11,0)) -> 3111.8398 | N10: =IF(12>VALUE(Financeiro!$B$23),"",IFERROR(N8/(1+Financeiro!B25)^12,0)) -> 3060.5388 | O10: =IF(13>VALUE(Financeiro!$B$23),"",IFERROR(O8/(1+Financeiro!B25)^13,0)) -> 3009.849 | P10: =IF(14>VALUE(Financeiro!$B$23),"",IFERROR(P8/(1+Financeiro!B25)^14,0)) -> 2959.7813 | Q10: =IF(15>VALUE(Financeiro!$B$23),"",IFERROR(Q8/(1+Financeiro!B25)^15,0)) -> 2910.3449 | R10: =IF(16>VALUE(Financeiro!$B$23),"",IFERROR(R8/(1+Financeiro!B25)^16,0)) -> 2861.5472 | S10: =IF(17>VALUE(Financeiro!$B$23),"",IFERROR(S8/(1+Financeiro!B25)^17,0)) -> 2813.3942 | T10: =IF(18>VALUE(Financeiro!$B$23),"",IFERROR(T8/(1+Financeiro!B25)^18,0)) -> 2765.8907 | U10: =IF(19>VALUE(Financeiro!$B$23),"",IFERROR(U8/(1+Financeiro!B25)^19,0)) -> 2719.0401 | V10: =IF(20>VALUE(Financeiro!$B$23),"",IFERROR(V8/(1+Financeiro!B25)^20,0)) -> 2672.8446 | W10: =IF(21>VALUE(Financeiro!$B$23),"",IFERROR(W8/(1+Financeiro!B25)^21,0)) -> 2627.3056 | X10: =IF(22>VALUE(Financeiro!$B$23),"",IFERROR(X8/(1+Financeiro!B25)^22,0)) -> 2582.4233 | Y10: =IF(23>VALUE(Financeiro!$B$23),"",IFERROR(Y8/(1+Financeiro!B25)^23,0)) -> 2538.1972 | Z10: =IF(24>VALUE(Financeiro!$B$23),"",IFERROR(Z8/(1+Financeiro!B25)^24,0)) -> 2494.626 | AA10: =IF(25>VALUE(Financeiro!$B$23),"",IFERROR(AA8/(1+Financeiro!B25)^25,0))
A11: Fluxo Descontado Acumulado (R$) | B11: =-Financeiro!B20 -> -36000 | C11: =IF(1>VALUE(Financeiro!$B$23),"",IFERROR(B11+C10,0)) -> -32345.517 | D11: =IF(2>VALUE(Financeiro!$B$23),"",IFERROR(C11+D10,0)) -> -28747.338 | E11: =IF(3>VALUE(Financeiro!$B$23),"",IFERROR(D11+E10,0)) -> -25205.098 | F11: =IF(4>VALUE(Financeiro!$B$23),"",IFERROR(E11+F10,0)) -> -21718.391 | G11: =IF(5>VALUE(Financeiro!$B$23),"",IFERROR(F11+G10,0)) -> -18286.778 | H11: =IF(6>VALUE(Financeiro!$B$23),"",IFERROR(G11+H10,0)) -> -14909.787 | I11: =IF(7>VALUE(Financeiro!$B$23),"",IFERROR(H11+I10,0)) -> -11586.917 | J11: =IF(8>VALUE(Financeiro!$B$23),"",IFERROR(I11+J10,0)) -> -8317.6448 | K11: =IF(9>VALUE(Financeiro!$B$23),"",IFERROR(J11+K10,0)) -> -5101.4221 | L11: =IF(10>VALUE(Financeiro!$B$23),"",IFERROR(K11+L10,0)) -> -1937.6828 | M11: =IF(11>VALUE(Financeiro!$B$23),"",IFERROR(L11+M10,0)) -> 1174.1571 | N11: =IF(12>VALUE(Financeiro!$B$23),"",IFERROR(M11+N10,0)) -> 4234.6958 | O11: =IF(13>VALUE(Financeiro!$B$23),"",IFERROR(N11+O10,0)) -> 7244.5448 | P11: =IF(14>VALUE(Financeiro!$B$23),"",IFERROR(O11+P10,0)) -> 10204.326 | Q11: =IF(15>VALUE(Financeiro!$B$23),"",IFERROR(P11+Q10,0)) -> 13114.671 | R11: =IF(16>VALUE(Financeiro!$B$23),"",IFERROR(Q11+R10,0)) -> 15976.218 | S11: =IF(17>VALUE(Financeiro!$B$23),"",IFERROR(R11+S10,0)) -> 18789.612 | T11: =IF(18>VALUE(Financeiro!$B$23),"",IFERROR(S11+T10,0)) -> 21555.503 | U11: =IF(19>VALUE(Financeiro!$B$23),"",IFERROR(T11+U10,0)) -> 24274.543 | V11: =IF(20>VALUE(Financeiro!$B$23),"",IFERROR(U11+V10,0)) -> 26947.388 | W11: =IF(21>VALUE(Financeiro!$B$23),"",IFERROR(V11+W10,0)) -> 29574.693 | X11: =IF(22>VALUE(Financeiro!$B$23),"",IFERROR(W11+X10,0)) -> 32157.117 | Y11: =IF(23>VALUE(Financeiro!$B$23),"",IFERROR(X11+Y10,0)) -> 34695.314 | Z11: =IF(24>VALUE(Financeiro!$B$23),"",IFERROR(Y11+Z10,0)) -> 37189.94 | AA11: =IF(25>VALUE(Financeiro!$B$23),"",IFERROR(Z11+AA10,0))
A13: CENÁRIO 3 — ARBITRAGEM + FV
A14: CAPEX Inicial (R$) | B14: =-Financeiro!B20 -> -36000 | C14: 0 | D14: 0 | E14: 0 | F14: 0 | G14: 0 | H14: 0 | I14: 0 | J14: 0 | K14: 0 | L14: 0 | M14: 0 | N14: 0 | O14: 0 | P14: 0 | Q14: 0 | R14: 0 | S14: 0 | T14: 0 | U14: 0 | V14: 0 | W14: 0 | X14: 0 | Y14: 0 | Z14: 0 | AA14: 0
A15: Economia Anual (R$) | B15: 0 | C15: =IF(COLUMN()-2>VALUE(Financeiro!$B$23),"",IFERROR((('C3 — Arbitragem + FV'!$B$21+'C3 — Arbitragem + FV'!$B$23+'C3 — Arbitragem + FV'!$B$30)+('C3 — Arbitragem + FV'!$B$9*(Premissas!$B$69-(Premissas!$B$76/(1-Premissas!$B$75)*IF(COLUMN()-2<=1,0.6,IF(COLUMN()-2<=2,0.75,0.9))))))*12*(1+Financeiro!$B$24)^(COLUMN()-2),0)) -> 8173.7917 | D15: =IF(COLUMN()-2>VALUE(Financeiro!$B$23),"",IFERROR((('C3 — Arbitragem + FV'!$B$21+'C3 — Arbitragem + FV'!$B$23+'C3 — Arbitragem + FV'!$B$30)+('C3 — Arbitragem + FV'!$B$9*(Premissas!$B$69-(Premissas!$B$76/(1-Premissas!$B$75)*IF(COLUMN()-2<=1,0.6,IF(COLUMN()-2<=2,0.75,0.9))))))*12*(1+Financeiro!$B$24)^(COLUMN()-2),0)) -> 8961.4447 | E15: =IF(COLUMN()-2>VALUE(Financeiro!$B$23),"",IFERROR((('C3 — Arbitragem + FV'!$B$21+'C3 — Arbitragem + FV'!$B$23+'C3 — Arbitragem + FV'!$B$30)+('C3 — Arbitragem + FV'!$B$9*(Premissas!$B$69-(Premissas!$B$76/(1-Premissas!$B$75)*IF(COLUMN()-2<=1,0.6,IF(COLUMN()-2<=2,0.75,0.9))))))*12*(1+Financeiro!$B$24)^(COLUMN()-2),0)) -> 9824.8904 | F15: =IF(COLUMN()-2>VALUE(Financeiro!$B$23),"",IFERROR((('C3 — Arbitragem + FV'!$B$21+'C3 — Arbitragem + FV'!$B$23+'C3 — Arbitragem + FV'!$B$30)+('C3 — Arbitragem + FV'!$B$9*(Premissas!$B$69-(Premissas!$B$76/(1-Premissas!$B$75)*IF(COLUMN()-2<=1,0.6,IF(COLUMN()-2<=2,0.75,0.9))))))*12*(1+Financeiro!$B$24)^(COLUMN()-2),0)) -> 10807.379 | G15: =IF(COLUMN()-2>VALUE(Financeiro!$B$23),"",IFERROR((('C3 — Arbitragem + FV'!$B$21+'C3 — Arbitragem + FV'!$B$23+'C3 — Arbitragem + FV'!$B$30)+('C3 — Arbitragem + FV'!$B$9*(Premissas!$B$69-(Premissas!$B$76/(1-Premissas!$B$75)*IF(COLUMN()-2<=1,0.6,IF(COLUMN()-2<=2,0.75,0.9))))))*12*(1+Financeiro!$B$24)^(COLUMN()-2),0)) -> 11888.117 | H15: =IF(COLUMN()-2>VALUE(Financeiro!$B$23),"",IFERROR((('C3 — Arbitragem + FV'!$B$21+'C3 — Arbitragem + FV'!$B$23+'C3 — Arbitragem + FV'!$B$30)+('C3 — Arbitragem + FV'!$B$9*(Premissas!$B$69-(Premissas!$B$76/(1-Premissas!$B$75)*IF(COLUMN()-2<=1,0.6,IF(COLUMN()-2<=2,0.75,0.9))))))*12*(1+Financeiro!$B$24)^(COLUMN()-2),0)) -> 13076.929 | I15: =IF(COLUMN()-2>VALUE(Financeiro!$B$23),"",IFERROR((('C3 — Arbitragem + FV'!$B$21+'C3 — Arbitragem + FV'!$B$23+'C3 — Arbitragem + FV'!$B$30)+('C3 — Arbitragem + FV'!$B$9*(Premissas!$B$69-(Premissas!$B$76/(1-Premissas!$B$75)*IF(COLUMN()-2<=1,0.6,IF(COLUMN()-2<=2,0.75,0.9))))))*12*(1+Financeiro!$B$24)^(COLUMN()-2),0)) -> 14384.622 | J15: =IF(COLUMN()-2>VALUE(Financeiro!$B$23),"",IFERROR((('C3 — Arbitragem + FV'!$B$21+'C3 — Arbitragem + FV'!$B$23+'C3 — Arbitragem + FV'!$B$30)+('C3 — Arbitragem + FV'!$B$9*(Premissas!$B$69-(Premissas!$B$76/(1-Premissas!$B$75)*IF(COLUMN()-2<=1,0.6,IF(COLUMN()-2<=2,0.75,0.9))))))*12*(1+Financeiro!$B$24)^(COLUMN()-2),0)) -> 15823.084 | ... N15: =IF(COLUMN()-2>VALUE(Financeiro!$B$23),"",IFERROR((('C3 — Arbitragem + FV'!$B$21+'C3 — Arbitragem + FV'!$B$23+'C3 — Arbitragem + FV'!$B$30)+('C3 — Arbitragem + FV'!$B$9*(Premissas!$B$69-(Premissas!$B$76/(1-Premissas!$B$75)*IF(COLUMN()-2<=1,0.6,IF(COLUMN()-2<=2,0.75,0.9))))))*12*(1+Financeiro!$B$24)^(COLUMN()-2),0)) -> 23166.578 | O15: =IF(13>VALUE(Financeiro!$B$23),"",IFERROR('C3 — Arbitragem + FV'!B36*(1+Financeiro!B24)^13,0)) -> 25483.235 | P15: =IF(14>VALUE(Financeiro!$B$23),"",IFERROR('C3 — Arbitragem + FV'!B36*(1+Financeiro!B24)^14,0)) -> 28031.559 | Q15: =IF(15>VALUE(Financeiro!$B$23),"",IFERROR('C3 — Arbitragem + FV'!B36*(1+Financeiro!B24)^15,0)) -> 30834.715 | R15: =IF(16>VALUE(Financeiro!$B$23),"",IFERROR('C3 — Arbitragem + FV'!B36*(1+Financeiro!B24)^16,0)) -> 33918.186 | S15: =IF(17>VALUE(Financeiro!$B$23),"",IFERROR('C3 — Arbitragem + FV'!B36*(1+Financeiro!B24)^17,0)) -> 37310.005 | T15: =IF(18>VALUE(Financeiro!$B$23),"",IFERROR('C3 — Arbitragem + FV'!B36*(1+Financeiro!B24)^18,0)) -> 41041.005 | U15: =IF(19>VALUE(Financeiro!$B$23),"",IFERROR('C3 — Arbitragem + FV'!B36*(1+Financeiro!B24)^19,0)) -> 45145.106 | V15: =IF(20>VALUE(Financeiro!$B$23),"",IFERROR('C3 — Arbitragem + FV'!B36*(1+Financeiro!B24)^20,0)) -> 49659.616 | W15: =IF(21>VALUE(Financeiro!$B$23),"",IFERROR('C3 — Arbitragem + FV'!B36*(1+Financeiro!B24)^21,0)) -> 54625.578 | X15: =IF(22>VALUE(Financeiro!$B$23),"",IFERROR('C3 — Arbitragem + FV'!B36*(1+Financeiro!B24)^22,0)) -> 60088.136 | Y15: =IF(23>VALUE(Financeiro!$B$23),"",IFERROR('C3 — Arbitragem + FV'!B36*(1+Financeiro!B24)^23,0)) -> 66096.949 | Z15: =IF(24>VALUE(Financeiro!$B$23),"",IFERROR('C3 — Arbitragem + FV'!B36*(1+Financeiro!B24)^24,0)) -> 72706.644 | AA15: =IF(25>VALUE(Financeiro!$B$23),"",IFERROR('C3 — Arbitragem + FV'!B36*(1+Financeiro!B24)^25,0))
A16: O&M Anual (R$) | B16: 0 | C16: =IF(1>VALUE(Financeiro!$B$23),"",IFERROR(-Financeiro!B20*(Financeiro!B26)*(1+Financeiro!B30)^1,0)) -> -187.2 | D16: =IF(2>VALUE(Financeiro!$B$23),"",IFERROR(-Financeiro!B20*(Financeiro!B26)*(1+Financeiro!B30)^2,0)) -> -194.688 | E16: =IF(3>VALUE(Financeiro!$B$23),"",IFERROR(-Financeiro!B20*(Financeiro!B26)*(1+Financeiro!B30)^3,0)) -> -202.47552 | F16: =IF(4>VALUE(Financeiro!$B$23),"",IFERROR(-Financeiro!B20*(Financeiro!B26)*(1+Financeiro!B30)^4,0)) -> -210.57454 | G16: =IF(5>VALUE(Financeiro!$B$23),"",IFERROR(-Financeiro!B20*(Financeiro!B26)*(1+Financeiro!B30)^5,0)) -> -218.99752 | H16: =IF(6>VALUE(Financeiro!$B$23),"",IFERROR(-Financeiro!B20*(Financeiro!B26)*(1+Financeiro!B30)^6,0)) -> -227.75742 | I16: =IF(7>VALUE(Financeiro!$B$23),"",IFERROR(-Financeiro!B20*(Financeiro!B26)*(1+Financeiro!B30)^7,0)) -> -236.86772 | J16: =IF(8>VALUE(Financeiro!$B$23),"",IFERROR(-Financeiro!B20*(Financeiro!B26)*(1+Financeiro!B30)^8,0)) -> -246.34243 | K16: =IF(9>VALUE(Financeiro!$B$23),"",IFERROR(-Financeiro!B20*(Financeiro!B26)*(1+Financeiro!B30)^9,0)) -> -256.19613 | L16: =IF(10>VALUE(Financeiro!$B$23),"",IFERROR(-Financeiro!B20*(Financeiro!B26)*(1+Financeiro!B30)^10,0)) -> -266.44397 | M16: =IF(11>VALUE(Financeiro!$B$23),"",IFERROR(-Financeiro!B20*(Financeiro!B26)*(1+Financeiro!B30)^11,0)) -> -277.10173 | N16: =IF(12>VALUE(Financeiro!$B$23),"",IFERROR(-Financeiro!B20*(Financeiro!B26)*(1+Financeiro!B30)^12,0)) -> -288.1858 | O16: =IF(13>VALUE(Financeiro!$B$23),"",IFERROR(-Financeiro!B20*(Financeiro!B26)*(1+Financeiro!B30)^13,0)) -> -299.71323 | P16: =IF(14>VALUE(Financeiro!$B$23),"",IFERROR(-Financeiro!B20*(Financeiro!B26)*(1+Financeiro!B30)^14,0)) -> -311.70176 | Q16: =IF(15>VALUE(Financeiro!$B$23),"",IFERROR(-Financeiro!B20*(Financeiro!B26)*(1+Financeiro!B30)^15,0)) -> -324.16983 | R16: =IF(16>VALUE(Financeiro!$B$23),"",IFERROR(-Financeiro!B20*(Financeiro!B26)*(1+Financeiro!B30)^16,0)) -> -337.13662 | S16: =IF(17>VALUE(Financeiro!$B$23),"",IFERROR(-Financeiro!B20*(Financeiro!B26)*(1+Financeiro!B30)^17,0)) -> -350.62209 | T16: =IF(18>VALUE(Financeiro!$B$23),"",IFERROR(-Financeiro!B20*(Financeiro!B26)*(1+Financeiro!B30)^18,0)) -> -364.64697 | U16: =IF(19>VALUE(Financeiro!$B$23),"",IFERROR(-Financeiro!B20*(Financeiro!B26)*(1+Financeiro!B30)^19,0)) -> -379.23285 | V16: =IF(20>VALUE(Financeiro!$B$23),"",IFERROR(-Financeiro!B20*(Financeiro!B26)*(1+Financeiro!B30)^20,0)) -> -394.40217 | W16: =IF(21>VALUE(Financeiro!$B$23),"",IFERROR(-Financeiro!B20*(Financeiro!B26)*(1+Financeiro!B30)^21,0)) -> -410.17825 | X16: =IF(22>VALUE(Financeiro!$B$23),"",IFERROR(-Financeiro!B20*(Financeiro!B26)*(1+Financeiro!B30)^22,0)) -> -426.58538 | Y16: =IF(23>VALUE(Financeiro!$B$23),"",IFERROR(-Financeiro!B20*(Financeiro!B26)*(1+Financeiro!B30)^23,0)) -> -443.6488 | Z16: =IF(24>VALUE(Financeiro!$B$23),"",IFERROR(-Financeiro!B20*(Financeiro!B26)*(1+Financeiro!B30)^24,0)) -> -461.39475 | AA16: =IF(25>VALUE(Financeiro!$B$23),"",IFERROR(-Financeiro!B20*(Financeiro!B26)*(1+Financeiro!B30)^25,0))
A17: Fluxo Líquido (R$) | B17: =-Financeiro!B20 -> -36000 | C17: =IF(1>VALUE(Financeiro!$B$23),"",IFERROR(C15+C16,0)) -> 7986.5917 | D17: =IF(2>VALUE(Financeiro!$B$23),"",IFERROR(D15+D16,0)) -> 8766.7567 | E17: =IF(3>VALUE(Financeiro!$B$23),"",IFERROR(E15+E16,0)) -> 9622.4148 | F17: =IF(4>VALUE(Financeiro!$B$23),"",IFERROR(F15+F16,0)) -> 10596.805 | G17: =IF(5>VALUE(Financeiro!$B$23),"",IFERROR(G15+G16,0)) -> 11669.12 | H17: =IF(6>VALUE(Financeiro!$B$23),"",IFERROR(H15+H16,0)) -> 12849.172 | I17: =IF(7>VALUE(Financeiro!$B$23),"",IFERROR(I15+I16,0)) -> 14147.754 | J17: =IF(8>VALUE(Financeiro!$B$23),"",IFERROR(J15+J16,0)) -> 15576.742 | K17: =IF(9>VALUE(Financeiro!$B$23),"",IFERROR(K15+K16,0)) -> 17149.196 | L17: =IF(10>VALUE(Financeiro!$B$23),"",IFERROR(L15+L16,0)) -> 18879.488 | M17: =IF(11>VALUE(Financeiro!$B$23),"",IFERROR(M15+M16,0)) -> 20783.423 | N17: =IF(12>VALUE(Financeiro!$B$23),"",IFERROR(N15+N16,0)) -> 22878.392 | O17: =IF(13>VALUE(Financeiro!$B$23),"",IFERROR(O15+O16,0)) -> 25183.522 | P17: =IF(14>VALUE(Financeiro!$B$23),"",IFERROR(P15+P16,0)) -> 27719.857 | Q17: =IF(15>VALUE(Financeiro!$B$23),"",IFERROR(Q15+Q16,0)) -> 30510.545 | R17: =IF(16>VALUE(Financeiro!$B$23),"",IFERROR(R15+R16,0)) -> 33581.05 | S17: =IF(17>VALUE(Financeiro!$B$23),"",IFERROR(S15+S16,0)) -> 36959.383 | T17: =IF(18>VALUE(Financeiro!$B$23),"",IFERROR(T15+T16,0)) -> 40676.358 | U17: =IF(19>VALUE(Financeiro!$B$23),"",IFERROR(U15+U16,0)) -> 44765.873 | V17: =IF(20>VALUE(Financeiro!$B$23),"",IFERROR(V15+V16,0)) -> 49265.214 | W17: =IF(21>VALUE(Financeiro!$B$23),"",IFERROR(W15+W16,0)) -> 54215.4 | X17: =IF(22>VALUE(Financeiro!$B$23),"",IFERROR(X15+X16,0)) -> 59661.55 | Y17: =IF(23>VALUE(Financeiro!$B$23),"",IFERROR(Y15+Y16,0)) -> 65653.301 | Z17: =IF(24>VALUE(Financeiro!$B$23),"",IFERROR(Z15+Z16,0)) -> 72245.25 | AA17: =IF(25>VALUE(Financeiro!$B$23),"",IFERROR(AA15+AA16,0))
A18: Fluxo Acumulado (R$) | B18: =-Financeiro!B20 -> -36000 | C18: =IF(1>VALUE(Financeiro!$B$23),"",IFERROR(B18+C17,0)) -> -28013.408 | D18: =IF(2>VALUE(Financeiro!$B$23),"",IFERROR(C18+D17,0)) -> -19246.652 | E18: =IF(3>VALUE(Financeiro!$B$23),"",IFERROR(D18+E17,0)) -> -9624.2367 | F18: =IF(4>VALUE(Financeiro!$B$23),"",IFERROR(E18+F17,0)) -> 972.56813 | G18: =IF(5>VALUE(Financeiro!$B$23),"",IFERROR(F18+G17,0)) -> 12641.688 | H18: =IF(6>VALUE(Financeiro!$B$23),"",IFERROR(G18+H17,0)) -> 25490.86 | I18: =IF(7>VALUE(Financeiro!$B$23),"",IFERROR(H18+I17,0)) -> 39638.614 | J18: =IF(8>VALUE(Financeiro!$B$23),"",IFERROR(I18+J17,0)) -> 55215.356 | K18: =IF(9>VALUE(Financeiro!$B$23),"",IFERROR(J18+K17,0)) -> 72364.552 | L18: =IF(10>VALUE(Financeiro!$B$23),"",IFERROR(K18+L17,0)) -> 91244.04 | M18: =IF(11>VALUE(Financeiro!$B$23),"",IFERROR(L18+M17,0)) -> 112027.46 | N18: =IF(12>VALUE(Financeiro!$B$23),"",IFERROR(M18+N17,0)) -> 134905.85 | O18: =IF(13>VALUE(Financeiro!$B$23),"",IFERROR(N18+O17,0)) -> 160089.38 | P18: =IF(14>VALUE(Financeiro!$B$23),"",IFERROR(O18+P17,0)) -> 187809.23 | Q18: =IF(15>VALUE(Financeiro!$B$23),"",IFERROR(P18+Q17,0)) -> 218319.78 | R18: =IF(16>VALUE(Financeiro!$B$23),"",IFERROR(Q18+R17,0)) -> 251900.83 | S18: =IF(17>VALUE(Financeiro!$B$23),"",IFERROR(R18+S17,0)) -> 288860.21 | T18: =IF(18>VALUE(Financeiro!$B$23),"",IFERROR(S18+T17,0)) -> 329536.57 | U18: =IF(19>VALUE(Financeiro!$B$23),"",IFERROR(T18+U17,0)) -> 374302.44 | V18: =IF(20>VALUE(Financeiro!$B$23),"",IFERROR(U18+V17,0)) -> 423567.66 | W18: =IF(21>VALUE(Financeiro!$B$23),"",IFERROR(V18+W17,0)) -> 477783.06 | X18: =IF(22>VALUE(Financeiro!$B$23),"",IFERROR(W18+X17,0)) -> 537444.61 | Y18: =IF(23>VALUE(Financeiro!$B$23),"",IFERROR(X18+Y17,0)) -> 603097.91 | Z18: =IF(24>VALUE(Financeiro!$B$23),"",IFERROR(Y18+Z17,0)) -> 675343.16 | AA18: =IF(25>VALUE(Financeiro!$B$23),"",IFERROR(Z18+AA17,0))
A19: Fluxo Descontado (R$) | B19: =-Financeiro!B20 -> -36000 | C19: =IF(1>VALUE(Financeiro!$B$23),"",IFERROR(C17/(1+Financeiro!B25)^1,0)) -> 7130.8855 | D19: =IF(2>VALUE(Financeiro!$B$23),"",IFERROR(D17/(1+Financeiro!B25)^2,0)) -> 6988.8048 | E19: =IF(3>VALUE(Financeiro!$B$23),"",IFERROR(E17/(1+Financeiro!B25)^3,0)) -> 6849.0448 | F19: =IF(4>VALUE(Financeiro!$B$23),"",IFERROR(F17/(1+Financeiro!B25)^4,0)) -> 6734.4611 | G19: =IF(5>VALUE(Financeiro!$B$23),"",IFERROR(G17/(1+Financeiro!B25)^5,0)) -> 6621.372 | H19: =IF(6>VALUE(Financeiro!$B$23),"",IFERROR(H17/(1+Financeiro!B25)^6,0)) -> 6509.7902 | I19: =IF(7>VALUE(Financeiro!$B$23),"",IFERROR(I17/(1+Financeiro!B25)^7,0)) -> 6399.7255 | J19: =IF(8>VALUE(Financeiro!$B$23),"",IFERROR(J17/(1+Financeiro!B25)^8,0)) -> 6291.1847 | K19: =IF(9>VALUE(Financeiro!$B$23),"",IFERROR(K17/(1+Financeiro!B25)^9,0)) -> 6184.1722 | L19: =IF(10>VALUE(Financeiro!$B$23),"",IFERROR(L17/(1+Financeiro!B25)^10,0)) -> 6078.6898 | M19: =IF(11>VALUE(Financeiro!$B$23),"",IFERROR(M17/(1+Financeiro!B25)^11,0)) -> 5974.7376 | N19: =IF(12>VALUE(Financeiro!$B$23),"",IFERROR(N17/(1+Financeiro!B25)^12,0)) -> 5872.3133 | O19: =IF(13>VALUE(Financeiro!$B$23),"",IFERROR(O17/(1+Financeiro!B25)^13,0)) -> 5771.4133 | P19: =IF(14>VALUE(Financeiro!$B$23),"",IFERROR(P17/(1+Financeiro!B25)^14,0)) -> 5672.032 | Q19: =IF(15>VALUE(Financeiro!$B$23),"",IFERROR(Q17/(1+Financeiro!B25)^15,0)) -> 5574.1625 | R19: =IF(16>VALUE(Financeiro!$B$23),"",IFERROR(R17/(1+Financeiro!B25)^16,0)) -> 5477.7966 | S19: =IF(17>VALUE(Financeiro!$B$23),"",IFERROR(S17/(1+Financeiro!B25)^17,0)) -> 5382.9249 | T19: =IF(18>VALUE(Financeiro!$B$23),"",IFERROR(T17/(1+Financeiro!B25)^18,0)) -> 5289.537 | U19: =IF(19>VALUE(Financeiro!$B$23),"",IFERROR(U17/(1+Financeiro!B25)^19,0)) -> 5197.6212 | V19: =IF(20>VALUE(Financeiro!$B$23),"",IFERROR(V17/(1+Financeiro!B25)^20,0)) -> 5107.1654 | W19: =IF(21>VALUE(Financeiro!$B$23),"",IFERROR(W17/(1+Financeiro!B25)^21,0)) -> 5018.1563 | X19: =IF(22>VALUE(Financeiro!$B$23),"",IFERROR(X17/(1+Financeiro!B25)^22,0)) -> 4930.5803 | Y19: =IF(23>VALUE(Financeiro!$B$23),"",IFERROR(Y17/(1+Financeiro!B25)^23,0)) -> 4844.4228 | Z19: =IF(24>VALUE(Financeiro!$B$23),"",IFERROR(Z17/(1+Financeiro!B25)^24,0)) -> 4759.669 | AA19: =IF(25>VALUE(Financeiro!$B$23),"",IFERROR(AA17/(1+Financeiro!B25)^25,0))
A20: Fluxo Descontado Acumulado (R$) | B20: =-Financeiro!B20 -> -36000 | C20: =IF(1>VALUE(Financeiro!$B$23),"",IFERROR(B20+C19,0)) -> -28869.115 | D20: =IF(2>VALUE(Financeiro!$B$23),"",IFERROR(C20+D19,0)) -> -21880.31 | E20: =IF(3>VALUE(Financeiro!$B$23),"",IFERROR(D20+E19,0)) -> -15031.265 | F20: =IF(4>VALUE(Financeiro!$B$23),"",IFERROR(E20+F19,0)) -> -8296.8039 | G20: =IF(5>VALUE(Financeiro!$B$23),"",IFERROR(F20+G19,0)) -> -1675.4319 | H20: =IF(6>VALUE(Financeiro!$B$23),"",IFERROR(G20+H19,0)) -> 4834.3583 | I20: =IF(7>VALUE(Financeiro!$B$23),"",IFERROR(H20+I19,0)) -> 11234.084 | J20: =IF(8>VALUE(Financeiro!$B$23),"",IFERROR(I20+J19,0)) -> 17525.269 | K20: =IF(9>VALUE(Financeiro!$B$23),"",IFERROR(J20+K19,0)) -> 23709.441 | L20: =IF(10>VALUE(Financeiro!$B$23),"",IFERROR(K20+L19,0)) -> 29788.131 | M20: =IF(11>VALUE(Financeiro!$B$23),"",IFERROR(L20+M19,0)) -> 35762.868 | N20: =IF(12>VALUE(Financeiro!$B$23),"",IFERROR(M20+N19,0)) -> 41635.181 | O20: =IF(13>VALUE(Financeiro!$B$23),"",IFERROR(N20+O19,0)) -> 47406.595 | P20: =IF(14>VALUE(Financeiro!$B$23),"",IFERROR(O20+P19,0)) -> 53078.627 | Q20: =IF(15>VALUE(Financeiro!$B$23),"",IFERROR(P20+Q19,0)) -> 58652.789 | R20: =IF(16>VALUE(Financeiro!$B$23),"",IFERROR(Q20+R19,0)) -> 64130.586 | S20: =IF(17>VALUE(Financeiro!$B$23),"",IFERROR(R20+S19,0)) -> 69513.511 | T20: =IF(18>VALUE(Financeiro!$B$23),"",IFERROR(S20+T19,0)) -> 74803.048 | U20: =IF(19>VALUE(Financeiro!$B$23),"",IFERROR(T20+U19,0)) -> 80000.669 | V20: =IF(20>VALUE(Financeiro!$B$23),"",IFERROR(U20+V19,0)) -> 85107.834 | W20: =IF(21>VALUE(Financeiro!$B$23),"",IFERROR(V20+W19,0)) -> 90125.991 | X20: =IF(22>VALUE(Financeiro!$B$23),"",IFERROR(W20+X19,0)) -> 95056.571 | Y20: =IF(23>VALUE(Financeiro!$B$23),"",IFERROR(X20+Y19,0)) -> 99900.994 | Z20: =IF(24>VALUE(Financeiro!$B$23),"",IFERROR(Y20+Z19,0)) -> 104660.66 | AA20: =IF(25>VALUE(Financeiro!$B$23),"",IFERROR(Z20+AA19,0))
A23: RESUMO DOS INDICADORES FINANCEIROS
A24: Indicador | B24: C2 — Arbitragem | C24: C3 — Arbitragem + FV
A25: CAPEX Total (R$) | B25: =Financeiro!B20 -> 36000 | C25: =Financeiro!B20 -> 36000
A26: Economia Líquida — Ano 1 (R$) | B26: ='C2 — Arbitragem'!B31 -> 3891.1104 | C26: =IFERROR(C15,0) -> 8173.7917
A27: Payback Simples (anos) | B27: =IFERROR(Financeiro!B20/('C2 — Arbitragem'!B31),0) -> 9.2518578 | C27: =IFERROR(Financeiro!B20/C26,0) -> 4.4043207
A28: VPL (R$) | B28: =IFERROR(NPV(Financeiro!B25,C8:AA8)+B5,0) -> 37189.94 | C28: =IFERROR(NPV(Financeiro!B25,C17:AA17)+B14,0) -> 104660.66
A29: TIR (% a.a.) | B29: =IFERROR(IRR(B8:AA8,10%),0) -> 0.20140807 | C29: =IFERROR(IRR(B17:AA17,10%),0) -> 0.31894136
A30: Economia Acumulada (R$) | B30: =IFERROR(OFFSET(B9,0,Financeiro!B23),0) -> 335471.89 | C30: =IFERROR(OFFSET(B18,0,Financeiro!B23),0) -> 675343.16
A31: Horizonte de Análise (anos) | B31: =Financeiro!B23 -> 24 | C31: =Financeiro!B23 -> 24
